Workbook
Name REPAIR: #REF!
Name Tabel_Material: #REF!
Name SUBKON: #REF!
Name ANALISA: #REF!
Name Tabel_Sub_Contractor: #REF!
Name EQUIPMENT: #REF!
Name BOQ: #REF!
Name BAHAN: #REF!
Name Tabel_Alat: #REF!
Name Tabel_Upah: #REF!
Name MATERIAL: #REF!
Name LABOUR: #REF!

Sheet 1. BQ RAPL
B1: =IFERROR(__xludf.DUMMYFUNCTION("IMPORTRANGE(""https://docs.google.com/spreadsheets/d/1xXTZ6iashDzALZxE9Km6nYXccX51ap95QEp6rlrrs8E/edit?gid=666458065#gid=666458065"",""1. BQ RAPL!$B$1:$k"")"),"SUMMARY ITEM PEKERJAAN") -> SUMMARY ITEM PEKERJAAN
B3: =IFERROR(__xludf.DUMMYFUNCTION("""COMPUTED_VALUE"""),"RINCIAN KEGIATAN ") -> RINCIAN KEGIATAN | D3: =IFERROR(__xludf.DUMMYFUNCTION("""COMPUTED_VALUE"""),": Pembangunan ") -> : Pembangunan
B4: =IFERROR(__xludf.DUMMYFUNCTION("""COMPUTED_VALUE"""),"LOKASI KEGIATAN ") -> LOKASI KEGIATAN | D4: =IFERROR(__xludf.DUMMYFUNCTION("""COMPUTED_VALUE"""),": MWT Infra") -> : MWT Infra
B5: =IFERROR(__xludf.DUMMYFUNCTION("""COMPUTED_VALUE"""),"TAHUN ANGGARAN ") -> TAHUN ANGGARAN | D5: =IFERROR(__xludf.DUMMYFUNCTION("""COMPUTED_VALUE"""),": 2026") -> : 2026 | I5: =IFERROR(__xludf.DUMMYFUNCTION("""COMPUTED_VALUE""")," PERHATIAN : > ISI KOLOM WARNA KUNING ") -> PERHATIAN : > ISI KOLOM WARNA KUNING
D7: =IFERROR(__xludf.DUMMYFUNCTION("""COMPUTED_VALUE"""),"PIC: PROJECT MANAGER") -> PIC: PROJECT MANAGER | I7: =IFERROR(__xludf.DUMMYFUNCTION("""COMPUTED_VALUE"""),4.887009375E9) -> 4887009375
B9: =IFERROR(__xludf.DUMMYFUNCTION("""COMPUTED_VALUE"""),"NOMOR ITEM") -> NOMOR ITEM | C9: =IFERROR(__xludf.DUMMYFUNCTION("""COMPUTED_VALUE"""),"URAIAN PEKERJAAN") -> URAIAN PEKERJAAN | F9: =IFERROR(__xludf.DUMMYFUNCTION("""COMPUTED_VALUE"""),"SATUAN") -> SATUAN | G9: =IFERROR(__xludf.DUMMYFUNCTION("""COMPUTED_VALUE""")," HARGA SATUAN") -> HARGA SATUAN | H9: =IFERROR(__xludf.DUMMYFUNCTION("""COMPUTED_VALUE""")," KUANTITAS") -> KUANTITAS | I9: =IFERROR(__xludf.DUMMYFUNCTION("""COMPUTED_VALUE""")," JUMLAH HARGA") -> JUMLAH HARGA | J9: =IFERROR(__xludf.DUMMYFUNCTION("""COMPUTED_VALUE""")," KETERANGAN") -> KETERANGAN | M9: CATATAN :
B10: =IFERROR(__xludf.DUMMYFUNCTION("""COMPUTED_VALUE"""),"PEKERJAAN") -> PEKERJAAN | G10: =IFERROR(__xludf.DUMMYFUNCTION("""COMPUTED_VALUE""")," RAPL") -> RAPL | H10: =IFERROR(__xludf.DUMMYFUNCTION("""COMPUTED_VALUE""")," RAPL") -> RAPL | I10: =IFERROR(__xludf.DUMMYFUNCTION("""COMPUTED_VALUE""")," RAPL") -> RAPL | M10: 1. B1
B13: =IFERROR(__xludf.DUMMYFUNCTION("""COMPUTED_VALUE"""),"I") -> I | D13: =IFERROR(__xludf.DUMMYFUNCTION("""COMPUTED_VALUE""")," BIAYA LANGSUNG : ") -> BIAYA LANGSUNG : | K13: =IFERROR(__xludf.DUMMYFUNCTION("""COMPUTED_VALUE"""),"I") -> I
B15: =IFERROR(__xludf.DUMMYFUNCTION("""COMPUTED_VALUE"""),1.0) -> 1 | D15: =IFERROR(__xludf.DUMMYFUNCTION("""COMPUTED_VALUE""")," PERKERASAN BETON SEMEN ") -> PERKERASAN BETON SEMEN | K15: =IFERROR(__xludf.DUMMYFUNCTION("""COMPUTED_VALUE"""),1.0) -> 1
B16: =IFERROR(__xludf.DUMMYFUNCTION("""COMPUTED_VALUE"""),2.0) -> 2 | D16: =IFERROR(__xludf.DUMMYFUNCTION("""COMPUTED_VALUE""")," Cor beton readymix FS-45 fast track 7 hari ") -> Cor beton readymix FS-45 fast track 7 hari | F16: =IFERROR(__xludf.DUMMYFUNCTION("""COMPUTED_VALUE""")," m3") -> m3 | G16: =IFERROR(__xludf.DUMMYFUNCTION("""COMPUTED_VALUE"""),4000000.0) -> 4000000 | H16: =IFERROR(__xludf.DUMMYFUNCTION("""COMPUTED_VALUE"""),450.0) -> 450 | I16: =IFERROR(__xludf.DUMMYFUNCTION("""COMPUTED_VALUE"""),1.8E9) -> 1800000000 | K16: =IFERROR(__xludf.DUMMYFUNCTION("""COMPUTED_VALUE"""),2.0) -> 2
B17: =IFERROR(__xludf.DUMMYFUNCTION("""COMPUTED_VALUE"""),3.0) -> 3 | D17: =IFERROR(__xludf.DUMMYFUNCTION("""COMPUTED_VALUE""")," Agregat klas B ") -> Agregat klas B | F17: =IFERROR(__xludf.DUMMYFUNCTION("""COMPUTED_VALUE""")," m3") -> m3 | G17: =IFERROR(__xludf.DUMMYFUNCTION("""COMPUTED_VALUE"""),366000.0) -> 366000 | H17: =IFERROR(__xludf.DUMMYFUNCTION("""COMPUTED_VALUE"""),1250.0) -> 1250 | I17: =IFERROR(__xludf.DUMMYFUNCTION("""COMPUTED_VALUE"""),4.575E8) -> 457500000 | K17: =IFERROR(__xludf.DUMMYFUNCTION("""COMPUTED_VALUE"""),3.0) -> 3
I18: =IFERROR(__xludf.DUMMYFUNCTION("""COMPUTED_VALUE"""),0.0) -> 0
B19: =IFERROR(__xludf.DUMMYFUNCTION("""COMPUTED_VALUE"""),5.0) -> 5 | D19: =IFERROR(__xludf.DUMMYFUNCTION("""COMPUTED_VALUE""")," STRUKTUR ") -> STRUKTUR | I19: =IFERROR(__xludf.DUMMYFUNCTION("""COMPUTED_VALUE"""),0.0) -> 0 | K19: =IFERROR(__xludf.DUMMYFUNCTION("""COMPUTED_VALUE"""),5.0) -> 5
B20: =IFERROR(__xludf.DUMMYFUNCTION("""COMPUTED_VALUE"""),6.0) -> 6 | D20: =IFERROR(__xludf.DUMMYFUNCTION("""COMPUTED_VALUE""")," Beton mutu sedang Fc’=30 MPa untuk Footing ") -> Beton mutu sedang Fc’=30 MPa untuk Footing | F20: =IFERROR(__xludf.DUMMYFUNCTION("""COMPUTED_VALUE""")," m3") -> m3 | G20: =IFERROR(__xludf.DUMMYFUNCTION("""COMPUTED_VALUE"""),2525000.0) -> 2525000 | H20: =IFERROR(__xludf.DUMMYFUNCTION("""COMPUTED_VALUE"""),180.0) -> 180 | I20: =IFERROR(__xludf.DUMMYFUNCTION("""COMPUTED_VALUE"""),4.545E8) -> 454500000 | K20: =IFERROR(__xludf.DUMMYFUNCTION("""COMPUTED_VALUE"""),6.0) -> 6
B21: =IFERROR(__xludf.DUMMYFUNCTION("""COMPUTED_VALUE"""),7.0) -> 7 | D21: =IFERROR(__xludf.DUMMYFUNCTION("""COMPUTED_VALUE""")," Baja Tulangan U 39 Ulir ") -> Baja Tulangan U 39 Ulir | F21: =IFERROR(__xludf.DUMMYFUNCTION("""COMPUTED_VALUE""")," kg") -> kg | G21: =IFERROR(__xludf.DUMMYFUNCTION("""COMPUTED_VALUE"""),10400.0) -> 10400 | H21: =IFERROR(__xludf.DUMMYFUNCTION("""COMPUTED_VALUE"""),146156.25) -> 146156.25 | I21: =IFERROR(__xludf.DUMMYFUNCTION("""COMPUTED_VALUE"""),1.520025E9) -> 1520025000 | K21: =IFERROR(__xludf.DUMMYFUNCTION("""COMPUTED_VALUE"""),7.0) -> 7
B22: =IFERROR(__xludf.DUMMYFUNCTION("""COMPUTED_VALUE"""),8.0) -> 8 | D22: =IFERROR(__xludf.DUMMYFUNCTION("""COMPUTED_VALUE""")," Tiang Bor Beton, diameter 500 mm, Beton K-350 Slump 18±2 ") -> Tiang Bor Beton, diameter 500 mm, Beton K-350 Slump 18±2 | F22: =IFERROR(__xludf.DUMMYFUNCTION("""COMPUTED_VALUE""")," m'") -> m' | G22: =IFERROR(__xludf.DUMMYFUNCTION("""COMPUTED_VALUE"""),2225000.0) -> 2225000 | H22: =IFERROR(__xludf.DUMMYFUNCTION("""COMPUTED_VALUE"""),294.375) -> 294.375 | I22: =IFERROR(__xludf.DUMMYFUNCTION("""COMPUTED_VALUE"""),6.54984375E8) -> 654984375 | K22: =IFERROR(__xludf.DUMMYFUNCTION("""COMPUTED_VALUE"""),8.0) -> 8
I23: =IFERROR(__xludf.DUMMYFUNCTION("""COMPUTED_VALUE"""),0.0) -> 0
I24: =IFERROR(__xludf.DUMMYFUNCTION("""COMPUTED_VALUE"""),0.0) -> 0
I25: =IFERROR(__xludf.DUMMYFUNCTION("""COMPUTED_VALUE"""),0.0) -> 0
I26: =IFERROR(__xludf.DUMMYFUNCTION("""COMPUTED_VALUE"""),0.0) -> 0
I27: =IFERROR(__xludf.DUMMYFUNCTION("""COMPUTED_VALUE"""),0.0) -> 0
I28: =IFERROR(__xludf.DUMMYFUNCTION("""COMPUTED_VALUE"""),0.0) -> 0
I29: =IFERROR(__xludf.DUMMYFUNCTION("""COMPUTED_VALUE"""),0.0) -> 0
I30: =IFERROR(__xludf.DUMMYFUNCTION("""COMPUTED_VALUE"""),0.0) -> 0
I31: =IFERROR(__xludf.DUMMYFUNCTION("""COMPUTED_VALUE"""),0.0) -> 0
I32: =IFERROR(__xludf.DUMMYFUNCTION("""COMPUTED_VALUE"""),0.0) -> 0
I33: =IFERROR(__xludf.DUMMYFUNCTION("""COMPUTED_VALUE"""),0.0) -> 0
I34: =IFERROR(__xludf.DUMMYFUNCTION("""COMPUTED_VALUE"""),0.0) -> 0
... I223: =IFERROR(__xludf.DUMMYFUNCTION("""COMPUTED_VALUE"""),0.0) -> 0
I503: =IFERROR(__xludf.DUMMYFUNCTION("""COMPUTED_VALUE"""),4.887009375E9) -> 4887009375

Sheet 2. SMDA BHN
A1: =IFERROR(__xludf.DUMMYFUNCTION("IMPORTRANGE(""https://docs.google.com/spreadsheets/d/1xXTZ6iashDzALZxE9Km6nYXccX51ap95QEp6rlrrs8E/edit?gid=870182660#gid=870182660"",""2. SMDA BHN!$A$1:$S"")"),"HARGA DASAR SATUAN BAHAN") -> HARGA DASAR SATUAN BAHAN
A3: =IFERROR(__xludf.DUMMYFUNCTION("""COMPUTED_VALUE"""),"RINCIAN KEGIATAN ") -> RINCIAN KEGIATAN | D3: =IFERROR(__xludf.DUMMYFUNCTION("""COMPUTED_VALUE"""),": Pembangunan ") -> : Pembangunan | T3: CATATAN :
A4: =IFERROR(__xludf.DUMMYFUNCTION("""COMPUTED_VALUE"""),"LOKASI KEGIATAN ") -> LOKASI KEGIATAN | D4: =IFERROR(__xludf.DUMMYFUNCTION("""COMPUTED_VALUE"""),": MWT Infra") -> : MWT Infra | T4: 1. A1
A5: =IFERROR(__xludf.DUMMYFUNCTION("""COMPUTED_VALUE"""),"TAHUN ANGGARAN ") -> TAHUN ANGGARAN | D5: =IFERROR(__xludf.DUMMYFUNCTION("""COMPUTED_VALUE"""),": 2026") -> : 2026 | G5: =IFERROR(__xludf.DUMMYFUNCTION("""COMPUTED_VALUE"""),"PERHATIAN : > ISI KOLOM WARNA KUNING ") -> PERHATIAN : > ISI KOLOM WARNA KUNING
B7: =IFERROR(__xludf.DUMMYFUNCTION("""COMPUTED_VALUE""")," PIC: PROJECT MANAGER") -> PIC: PROJECT MANAGER | D7: =IFERROR(__xludf.DUMMYFUNCTION("""COMPUTED_VALUE"""),"T O T A L") -> T O T A L | H7: =IFERROR(__xludf.DUMMYFUNCTION("""COMPUTED_VALUE"""),4.38710625E9) -> 4387106250 | M7: =IFERROR(__xludf.DUMMYFUNCTION("""COMPUTED_VALUE""")," KONVERSI DATA KE KODE AKUN TAS") -> KONVERSI DATA KE KODE AKUN TAS | Q7: =IFERROR(__xludf.DUMMYFUNCTION("""COMPUTED_VALUE""")," KONVERSI DATA KE KODE BARANG TAS") -> KONVERSI DATA KE KODE BARANG TAS
A9: =IFERROR(__xludf.DUMMYFUNCTION("""COMPUTED_VALUE"""),"No") -> No | B9: =IFERROR(__xludf.DUMMYFUNCTION("""COMPUTED_VALUE"""),"URAIAN") -> URAIAN | C9: =IFERROR(__xludf.DUMMYFUNCTION("""COMPUTED_VALUE"""),"KODE AKUN") -> KODE AKUN | D9: =IFERROR(__xludf.DUMMYFUNCTION("""COMPUTED_VALUE"""),"KODE MATERIAL ") -> KODE MATERIAL | E9: =IFERROR(__xludf.DUMMYFUNCTION("""COMPUTED_VALUE"""),"SATUAN") -> SATUAN | F9: =IFERROR(__xludf.DUMMYFUNCTION("""COMPUTED_VALUE""")," KUANTITAS ") -> KUANTITAS | G9: =IFERROR(__xludf.DUMMYFUNCTION("""COMPUTED_VALUE"""),"HARGA SATUAN (Rp.)") -> HARGA SATUAN (Rp.) | H9: =IFERROR(__xludf.DUMMYFUNCTION("""COMPUTED_VALUE"""),"JUMLAH HARGA (Rp.)") -> JUMLAH HARGA (Rp.) | J9: =IFERROR(__xludf.DUMMYFUNCTION("""COMPUTED_VALUE""")," KOLOM BANTUAN ") -> KOLOM BANTUAN | M9: =IFERROR(__xludf.DUMMYFUNCTION("""COMPUTED_VALUE""")," DATA UNTUK INPUT TAS") -> DATA UNTUK INPUT TAS | Q9: =IFERROR(__xludf.DUMMYFUNCTION("""COMPUTED_VALUE"""),"DATA UNTUK INPUT TAS") -> DATA UNTUK INPUT TAS
A10: =IFERROR(__xludf.DUMMYFUNCTION("""COMPUTED_VALUE"""),"A") -> A | B10: =IFERROR(__xludf.DUMMYFUNCTION("""COMPUTED_VALUE"""),"B") -> B | C10: =IFERROR(__xludf.DUMMYFUNCTION("""COMPUTED_VALUE"""),"C") -> C | D10: =IFERROR(__xludf.DUMMYFUNCTION("""COMPUTED_VALUE"""),"D") -> D | E10: =IFERROR(__xludf.DUMMYFUNCTION("""COMPUTED_VALUE"""),"E") -> E | F10: =IFERROR(__xludf.DUMMYFUNCTION("""COMPUTED_VALUE"""),"F") -> F | G10: =IFERROR(__xludf.DUMMYFUNCTION("""COMPUTED_VALUE"""),"G") -> G | H10: =IFERROR(__xludf.DUMMYFUNCTION("""COMPUTED_VALUE"""),"H= (F x G)") -> H= (F x G) | M10: =IFERROR(__xludf.DUMMYFUNCTION("""COMPUTED_VALUE"""),"KODE AKUN") -> KODE AKUN | N10: =IFERROR(__xludf.DUMMYFUNCTION("""COMPUTED_VALUE"""),"NAMA AKUN") -> NAMA AKUN | O10: =IFERROR(__xludf.DUMMYFUNCTION("""COMPUTED_VALUE"""),"SATUAN") -> SATUAN | Q10: =IFERROR(__xludf.DUMMYFUNCTION("""COMPUTED_VALUE"""),"KODE BARANG") -> KODE BARANG | R10: =IFERROR(__xludf.DUMMYFUNCTION("""COMPUTED_VALUE"""),"NAMA BARANG") -> NAMA BARANG | S10: =IFERROR(__xludf.DUMMYFUNCTION("""COMPUTED_VALUE"""),"SATUAN") -> SATUAN
A12: =IFERROR(__xludf.DUMMYFUNCTION("""COMPUTED_VALUE"""),1.0) -> 1 | B12: =IFERROR(__xludf.DUMMYFUNCTION("""COMPUTED_VALUE"""),"Agregat klas B") -> Agregat klas B | C12: =IFERROR(__xludf.DUMMYFUNCTION("""COMPUTED_VALUE"""),1.0) -> 1 | D12: =IFERROR(__xludf.DUMMYFUNCTION("""COMPUTED_VALUE"""),"M001") -> M001 | E12: =IFERROR(__xludf.DUMMYFUNCTION("""COMPUTED_VALUE"""),"M3") -> M3 | F12: =IFERROR(__xludf.DUMMYFUNCTION("""COMPUTED_VALUE"""),1250.0) -> 1250 | G12: =IFERROR(__xludf.DUMMYFUNCTION("""COMPUTED_VALUE"""),275000.0) -> 275000 | H12: =IFERROR(__xludf.DUMMYFUNCTION("""COMPUTED_VALUE"""),3.4375E8) -> 343750000 | J12: =IFERROR(__xludf.DUMMYFUNCTION("""COMPUTED_VALUE""")," Agregat klas B ") -> Agregat klas B | M12: =IFERROR(__xludf.DUMMYFUNCTION("""COMPUTED_VALUE"""),1.0) -> 1 | N12: =IFERROR(__xludf.DUMMYFUNCTION("""COMPUTED_VALUE""")," Agregat klas B") -> Agregat klas B | O12: =IFERROR(__xludf.DUMMYFUNCTION("""COMPUTED_VALUE"""),"M3") -> M3 | Q12: =IFERROR(__xludf.DUMMYFUNCTION("""COMPUTED_VALUE"""),20.0) -> 20 | R12: =IFERROR(__xludf.DUMMYFUNCTION("""COMPUTED_VALUE""")," Agregat klas B ") -> Agregat klas B | S12: =IFERROR(__xludf.DUMMYFUNCTION("""COMPUTED_VALUE"""),"M3") -> M3
A13: =IFERROR(__xludf.DUMMYFUNCTION("""COMPUTED_VALUE"""),2.0) -> 2 | B13: =IFERROR(__xludf.DUMMYFUNCTION("""COMPUTED_VALUE"""),"Baja Tul Ulir") -> Baja Tul Ulir | C13: =IFERROR(__xludf.DUMMYFUNCTION("""COMPUTED_VALUE"""),2.0) -> 2 | D13: =IFERROR(__xludf.DUMMYFUNCTION("""COMPUTED_VALUE"""),"M002") -> M002 | E13: =IFERROR(__xludf.DUMMYFUNCTION("""COMPUTED_VALUE"""),"KG") -> KG | F13: =IFERROR(__xludf.DUMMYFUNCTION("""COMPUTED_VALUE"""),146156.25) -> 146156.25 | G13: =IFERROR(__xludf.DUMMYFUNCTION("""COMPUTED_VALUE"""),8500.0) -> 8500 | H13: =IFERROR(__xludf.DUMMYFUNCTION("""COMPUTED_VALUE"""),1.242328125E9) -> 1242328125 | J13: =IFERROR(__xludf.DUMMYFUNCTION("""COMPUTED_VALUE""")," Baja Tul Ulir ") -> Baja Tul Ulir | M13: =IFERROR(__xludf.DUMMYFUNCTION("""COMPUTED_VALUE"""),2.0) -> 2 | N13: =IFERROR(__xludf.DUMMYFUNCTION("""COMPUTED_VALUE""")," Baja Tul Ulir") -> Baja Tul Ulir | O13: =IFERROR(__xludf.DUMMYFUNCTION("""COMPUTED_VALUE"""),"KG") -> KG | Q13: =IFERROR(__xludf.DUMMYFUNCTION("""COMPUTED_VALUE"""),21.0) -> 21 | R13: =IFERROR(__xludf.DUMMYFUNCTION("""COMPUTED_VALUE""")," Baja Tul Ulir ") -> Baja Tul Ulir | S13: =IFERROR(__xludf.DUMMYFUNCTION("""COMPUTED_VALUE"""),"KG") -> KG
A14: =IFERROR(__xludf.DUMMYFUNCTION("""COMPUTED_VALUE"""),3.0) -> 3 | B14: =IFERROR(__xludf.DUMMYFUNCTION("""COMPUTED_VALUE"""),"Beton Ready fc' 30 MPa") -> Beton Ready fc' 30 MPa | C14: =IFERROR(__xludf.DUMMYFUNCTION("""COMPUTED_VALUE"""),3.0) -> 3 | D14: =IFERROR(__xludf.DUMMYFUNCTION("""COMPUTED_VALUE"""),"M003") -> M003 | E14: =IFERROR(__xludf.DUMMYFUNCTION("""COMPUTED_VALUE"""),"M3") -> M3 | F14: =IFERROR(__xludf.DUMMYFUNCTION("""COMPUTED_VALUE"""),474.375) -> 474.375 | G14: =IFERROR(__xludf.DUMMYFUNCTION("""COMPUTED_VALUE"""),1040000.0) -> 1040000 | H14: =IFERROR(__xludf.DUMMYFUNCTION("""COMPUTED_VALUE"""),4.9335E8) -> 493350000 | J14: =IFERROR(__xludf.DUMMYFUNCTION("""COMPUTED_VALUE""")," Beton Ready fc' 30 MPa ") -> Beton Ready fc' 30 MPa | M14: =IFERROR(__xludf.DUMMYFUNCTION("""COMPUTED_VALUE"""),3.0) -> 3 | N14: =IFERROR(__xludf.DUMMYFUNCTION("""COMPUTED_VALUE""")," Beton Ready fc' 30 MPa") -> Beton Ready fc' 30 MPa | O14: =IFERROR(__xludf.DUMMYFUNCTION("""COMPUTED_VALUE"""),"M3") -> M3 | Q14: =IFERROR(__xludf.DUMMYFUNCTION("""COMPUTED_VALUE"""),22.0) -> 22 | R14: =IFERROR(__xludf.DUMMYFUNCTION("""COMPUTED_VALUE""")," Beton Ready fc' 30 MPa ") -> Beton Ready fc' 30 MPa | S14: =IFERROR(__xludf.DUMMYFUNCTION("""COMPUTED_VALUE"""),"M3") -> M3
A15: =IFERROR(__xludf.DUMMYFUNCTION("""COMPUTED_VALUE"""),4.0) -> 4 | B15: =IFERROR(__xludf.DUMMYFUNCTION("""COMPUTED_VALUE"""),"Beton Ready Mix fs' 45, Slump 12±2") -> Beton Ready Mix fs' 45, Slump 12±2 | C15: =IFERROR(__xludf.DUMMYFUNCTION("""COMPUTED_VALUE"""),4.0) -> 4 | D15: =IFERROR(__xludf.DUMMYFUNCTION("""COMPUTED_VALUE"""),"M004") -> M004 | E15: =IFERROR(__xludf.DUMMYFUNCTION("""COMPUTED_VALUE"""),"M3") -> M3 | F15: =IFERROR(__xludf.DUMMYFUNCTION("""COMPUTED_VALUE"""),1500.0) -> 1500 | G15: =IFERROR(__xludf.DUMMYFUNCTION("""COMPUTED_VALUE"""),1195000.0) -> 1195000 | H15: =IFERROR(__xludf.DUMMYFUNCTION("""COMPUTED_VALUE"""),1.7925E9) -> 1792500000 | J15: =IFERROR(__xludf.DUMMYFUNCTION("""COMPUTED_VALUE""")," Beton Ready Mix fs' 45, Slump 12±2 ") -> Beton Ready Mix fs' 45, Slump 12±2 | M15: =IFERROR(__xludf.DUMMYFUNCTION("""COMPUTED_VALUE"""),4.0) -> 4 | N15: =IFERROR(__xludf.DUMMYFUNCTION("""COMPUTED_VALUE""")," Beton Ready Mix fs' 45, Slump 12±2") -> Beton Ready Mix fs' 45, Slump 12±2 | O15: =IFERROR(__xludf.DUMMYFUNCTION("""COMPUTED_VALUE"""),"M3") -> M3 | Q15: =IFERROR(__xludf.DUMMYFUNCTION("""COMPUTED_VALUE"""),23.0) -> 23 | R15: =IFERROR(__xludf.DUMMYFUNCTION("""COMPUTED_VALUE""")," Beton Ready Mix fs' 45, Slump 12±2 ") -> Beton Ready Mix fs' 45, Slump 12±2 | S15: =IFERROR(__xludf.DUMMYFUNCTION("""COMPUTED_VALUE"""),"M3") -> M3
A16: =IFERROR(__xludf.DUMMYFUNCTION("""COMPUTED_VALUE"""),5.0) -> 5 | B16: =IFERROR(__xludf.DUMMYFUNCTION("""COMPUTED_VALUE"""),"Kawat Bendrat") -> Kawat Bendrat | C16: =IFERROR(__xludf.DUMMYFUNCTION("""COMPUTED_VALUE"""),5.0) -> 5 | D16: =IFERROR(__xludf.DUMMYFUNCTION("""COMPUTED_VALUE"""),"M005") -> M005 | E16: =IFERROR(__xludf.DUMMYFUNCTION("""COMPUTED_VALUE"""),"KG") -> KG | F16: =IFERROR(__xludf.DUMMYFUNCTION("""COMPUTED_VALUE"""),3653.90625) -> 3653.9062 | G16: =IFERROR(__xludf.DUMMYFUNCTION("""COMPUTED_VALUE"""),20000.0) -> 20000 | H16: =IFERROR(__xludf.DUMMYFUNCTION("""COMPUTED_VALUE"""),7.3078125E7) -> 73078125 | J16: =IFERROR(__xludf.DUMMYFUNCTION("""COMPUTED_VALUE""")," Kawat Bendrat ") -> Kawat Bendrat | M16: =IFERROR(__xludf.DUMMYFUNCTION("""COMPUTED_VALUE"""),5.0) -> 5 | N16: =IFERROR(__xludf.DUMMYFUNCTION("""COMPUTED_VALUE""")," Kawat Bendrat") -> Kawat Bendrat | O16: =IFERROR(__xludf.DUMMYFUNCTION("""COMPUTED_VALUE"""),"KG") -> KG | Q16: =IFERROR(__xludf.DUMMYFUNCTION("""COMPUTED_VALUE"""),24.0) -> 24 | R16: =IFERROR(__xludf.DUMMYFUNCTION("""COMPUTED_VALUE""")," Kawat Bendrat ") -> Kawat Bendrat | S16: =IFERROR(__xludf.DUMMYFUNCTION("""COMPUTED_VALUE"""),"KG") -> KG
A17: =IFERROR(__xludf.DUMMYFUNCTION("""COMPUTED_VALUE"""),6.0) -> 6 | B17: =IFERROR(__xludf.DUMMYFUNCTION("""COMPUTED_VALUE"""),"Kayu 5/7") -> Kayu 5/7 | C17: =IFERROR(__xludf.DUMMYFUNCTION("""COMPUTED_VALUE"""),6.0) -> 6 | D17: =IFERROR(__xludf.DUMMYFUNCTION("""COMPUTED_VALUE"""),"M006") -> M006 | E17: =IFERROR(__xludf.DUMMYFUNCTION("""COMPUTED_VALUE"""),"M3") -> M3 | F17: =IFERROR(__xludf.DUMMYFUNCTION("""COMPUTED_VALUE"""),3.0) -> 3 | G17: =IFERROR(__xludf.DUMMYFUNCTION("""COMPUTED_VALUE"""),2000000.0) -> 2000000 | H17: =IFERROR(__xludf.DUMMYFUNCTION("""COMPUTED_VALUE"""),6000000.0) -> 6000000 | J17: =IFERROR(__xludf.DUMMYFUNCTION("""COMPUTED_VALUE""")," Kayu 5/7 ") -> Kayu 5/7 | M17: =IFERROR(__xludf.DUMMYFUNCTION("""COMPUTED_VALUE"""),6.0) -> 6 | N17: =IFERROR(__xludf.DUMMYFUNCTION("""COMPUTED_VALUE""")," Kayu 5/7") -> Kayu 5/7 | O17: =IFERROR(__xludf.DUMMYFUNCTION("""COMPUTED_VALUE"""),"M3") -> M3 | Q17: =IFERROR(__xludf.DUMMYFUNCTION("""COMPUTED_VALUE"""),25.0) -> 25 | R17: =IFERROR(__xludf.DUMMYFUNCTION("""COMPUTED_VALUE""")," MTRL BEKISTING ") -> MTRL BEKISTING | S17: =IFERROR(__xludf.DUMMYFUNCTION("""COMPUTED_VALUE"""),"M2") -> M2
A18: =IFERROR(__xludf.DUMMYFUNCTION("""COMPUTED_VALUE"""),7.0) -> 7 | B18: =IFERROR(__xludf.DUMMYFUNCTION("""COMPUTED_VALUE"""),"Multipleks 18 mm") -> Multipleks 18 mm | C18: =IFERROR(__xludf.DUMMYFUNCTION("""COMPUTED_VALUE"""),7.0) -> 7 | D18: =IFERROR(__xludf.DUMMYFUNCTION("""COMPUTED_VALUE"""),"M007") -> M007 | E18: =IFERROR(__xludf.DUMMYFUNCTION("""COMPUTED_VALUE"""),"LBR") -> LBR | F18: =IFERROR(__xludf.DUMMYFUNCTION("""COMPUTED_VALUE"""),60.0) -> 60 | G18: =IFERROR(__xludf.DUMMYFUNCTION("""COMPUTED_VALUE"""),250000.0) -> 250000 | H18: =IFERROR(__xludf.DUMMYFUNCTION("""COMPUTED_VALUE"""),1.5E7) -> 15000000 | J18: =IFERROR(__xludf.DUMMYFUNCTION("""COMPUTED_VALUE""")," Multipleks 18 mm ") -> Multipleks 18 mm | M18: =IFERROR(__xludf.DUMMYFUNCTION("""COMPUTED_VALUE"""),7.0) -> 7 | N18: =IFERROR(__xludf.DUMMYFUNCTION("""COMPUTED_VALUE""")," Multipleks 18 mm") -> Multipleks 18 mm | O18: =IFERROR(__xludf.DUMMYFUNCTION("""COMPUTED_VALUE"""),"LBR") -> LBR | Q18: =IFERROR(__xludf.DUMMYFUNCTION("""COMPUTED_VALUE"""),26.0) -> 26 | R18: =IFERROR(__xludf.DUMMYFUNCTION("""COMPUTED_VALUE""")," MTRL BEKISTING ") -> MTRL BEKISTING | S18: =IFERROR(__xludf.DUMMYFUNCTION("""COMPUTED_VALUE"""),"M2") -> M2
A19: =IFERROR(__xludf.DUMMYFUNCTION("""COMPUTED_VALUE"""),8.0) -> 8 | B19: =IFERROR(__xludf.DUMMYFUNCTION("""COMPUTED_VALUE"""),"Paku") -> Paku | C19: =IFERROR(__xludf.DUMMYFUNCTION("""COMPUTED_VALUE"""),8.0) -> 8 | D19: =IFERROR(__xludf.DUMMYFUNCTION("""COMPUTED_VALUE"""),"M008") -> M008 | E19: =IFERROR(__xludf.DUMMYFUNCTION("""COMPUTED_VALUE"""),"KG") -> KG | F19: =IFERROR(__xludf.DUMMYFUNCTION("""COMPUTED_VALUE"""),30.0) -> 30 | G19: =IFERROR(__xludf.DUMMYFUNCTION("""COMPUTED_VALUE"""),20000.0) -> 20000 | H19: =IFERROR(__xludf.DUMMYFUNCTION("""COMPUTED_VALUE"""),600000.0) -> 600000 | J19: =IFERROR(__xludf.DUMMYFUNCTION("""COMPUTED_VALUE""")," Paku ") -> Paku | M19: =IFERROR(__xludf.DUMMYFUNCTION("""COMPUTED_VALUE"""),8.0) -> 8 | N19: =IFERROR(__xludf.DUMMYFUNCTION("""COMPUTED_VALUE""")," MTRL PENUNJANG") -> MTRL PENUNJANG | O19: =IFERROR(__xludf.DUMMYFUNCTION("""COMPUTED_VALUE"""),"LS") -> LS | Q19: =IFERROR(__xludf.DUMMYFUNCTION("""COMPUTED_VALUE"""),27.0) -> 27 | R19: =IFERROR(__xludf.DUMMYFUNCTION("""COMPUTED_VALUE""")," MTRL BEKISTING ") -> MTRL BEKISTING | S19: =IFERROR(__xludf.DUMMYFUNCTION("""COMPUTED_VALUE"""),"M2") -> M2
A20: =IFERROR(__xludf.DUMMYFUNCTION("""COMPUTED_VALUE"""),9.0) -> 9 | B20: =IFERROR(__xludf.DUMMYFUNCTION("""COMPUTED_VALUE"""),"Concrete Mixer Beton") -> Concrete Mixer Beton | C20: =IFERROR(__xludf.DUMMYFUNCTION("""COMPUTED_VALUE"""),9.0) -> 9 | D20: =IFERROR(__xludf.DUMMYFUNCTION("""COMPUTED_VALUE"""),"M010") -> M010 | E20: =IFERROR(__xludf.DUMMYFUNCTION("""COMPUTED_VALUE"""),"UNIT") -> UNIT | F20: =IFERROR(__xludf.DUMMYFUNCTION("""COMPUTED_VALUE"""),1.0) -> 1 | G20: =IFERROR(__xludf.DUMMYFUNCTION("""COMPUTED_VALUE"""),2.5E7) -> 25000000 | H20: =IFERROR(__xludf.DUMMYFUNCTION("""COMPUTED_VALUE"""),2.5E7) -> 25000000 | J20: =IFERROR(__xludf.DUMMYFUNCTION("""COMPUTED_VALUE""")," Concrete Mixer Beton ") -> Concrete Mixer Beton | M20: =IFERROR(__xludf.DUMMYFUNCTION("""COMPUTED_VALUE"""),9.0) -> 9 | Q20: =IFERROR(__xludf.DUMMYFUNCTION("""COMPUTED_VALUE"""),28.0) -> 28
A21: =IFERROR(__xludf.DUMMYFUNCTION("""COMPUTED_VALUE"""),10.0) -> 10 | B21: =IFERROR(__xludf.DUMMYFUNCTION("""COMPUTED_VALUE"""),"Mesin gerinda tangan") -> Mesin gerinda tangan | C21: =IFERROR(__xludf.DUMMYFUNCTION("""COMPUTED_VALUE"""),10.0) -> 10 | D21: =IFERROR(__xludf.DUMMYFUNCTION("""COMPUTED_VALUE"""),"M011") -> M011 | E21: =IFERROR(__xludf.DUMMYFUNCTION("""COMPUTED_VALUE"""),"UNIT") -> UNIT | F21: =IFERROR(__xludf.DUMMYFUNCTION("""COMPUTED_VALUE"""),2.0) -> 2 | G21: =IFERROR(__xludf.DUMMYFUNCTION("""COMPUTED_VALUE"""),500000.0) -> 500000 | H21: =IFERROR(__xludf.DUMMYFUNCTION("""COMPUTED_VALUE"""),1000000.0) -> 1000000 | J21: =IFERROR(__xludf.DUMMYFUNCTION("""COMPUTED_VALUE""")," Mesin gerinda tangan ") -> Mesin gerinda tangan | M21: =IFERROR(__xludf.DUMMYFUNCTION("""COMPUTED_VALUE"""),10.0) -> 10 | N21: =IFERROR(__xludf.DUMMYFUNCTION("""COMPUTED_VALUE""")," Solar") -> Solar | O21: =IFERROR(__xludf.DUMMYFUNCTION("""COMPUTED_VALUE"""),"Liter") -> Liter | Q21: =IFERROR(__xludf.DUMMYFUNCTION("""COMPUTED_VALUE"""),29.0) -> 29 | R21: =IFERROR(__xludf.DUMMYFUNCTION("""COMPUTED_VALUE""")," Solar ") -> Solar | S21: =IFERROR(__xludf.DUMMYFUNCTION("""COMPUTED_VALUE"""),"Liter") -> Liter
A22: =IFERROR(__xludf.DUMMYFUNCTION("""COMPUTED_VALUE"""),11.0) -> 11 | B22: =IFERROR(__xludf.DUMMYFUNCTION("""COMPUTED_VALUE"""),"Rubber Cone") -> Rubber Cone | C22: =IFERROR(__xludf.DUMMYFUNCTION("""COMPUTED_VALUE"""),11.0) -> 11 | D22: =IFERROR(__xludf.DUMMYFUNCTION("""COMPUTED_VALUE"""),"M012") -> M012 | E22: =IFERROR(__xludf.DUMMYFUNCTION("""COMPUTED_VALUE"""),"BUAH") -> BUAH | F22: =IFERROR(__xludf.DUMMYFUNCTION("""COMPUTED_VALUE"""),20.0) -> 20 | G22: =IFERROR(__xludf.DUMMYFUNCTION("""COMPUTED_VALUE"""),100000.0) -> 100000 | H22: =IFERROR(__xludf.DUMMYFUNCTION("""COMPUTED_VALUE"""),2000000.0) -> 2000000 | J22: =IFERROR(__xludf.DUMMYFUNCTION("""COMPUTED_VALUE""")," Rubber Cone ") -> Rubber Cone | M22: =IFERROR(__xludf.DUMMYFUNCTION("""COMPUTED_VALUE"""),11.0) -> 11 | N22: =IFERROR(__xludf.DUMMYFUNCTION("""COMPUTED_VALUE""")," Pertalite") -> Pertalite | O22: =IFERROR(__xludf.DUMMYFUNCTION("""COMPUTED_VALUE"""),"Liter") -> Liter | Q22: =IFERROR(__xludf.DUMMYFUNCTION("""COMPUTED_VALUE"""),30.0) -> 30 | R22: =IFERROR(__xludf.DUMMYFUNCTION("""COMPUTED_VALUE""")," Pertalite ") -> Pertalite | S22: =IFERROR(__xludf.DUMMYFUNCTION("""COMPUTED_VALUE"""),"Liter") -> Liter
A23: =IFERROR(__xludf.DUMMYFUNCTION("""COMPUTED_VALUE"""),12.0) -> 12 | H23: =IFERROR(__xludf.DUMMYFUNCTION("""COMPUTED_VALUE"""),0.0) -> 0
A24: =IFERROR(__xludf.DUMMYFUNCTION("""COMPUTED_VALUE"""),13.0) -> 13 | H24: =IFERROR(__xludf.DUMMYFUNCTION("""COMPUTED_VALUE"""),0.0) -> 0
A25: =IFERROR(__xludf.DUMMYFUNCTION("""COMPUTED_VALUE"""),14.0) -> 14 | B25: =IFERROR(__xludf.DUMMYFUNCTION("""COMPUTED_VALUE"""),"Solar") -> Solar | C25: =IFERROR(__xludf.DUMMYFUNCTION("""COMPUTED_VALUE"""),12.0) -> 12 | D25: =IFERROR(__xludf.DUMMYFUNCTION("""COMPUTED_VALUE"""),"M014") -> M014 | E25: =IFERROR(__xludf.DUMMYFUNCTION("""COMPUTED_VALUE"""),"Liter") -> Liter | F25: =IFERROR(__xludf.DUMMYFUNCTION("""COMPUTED_VALUE"""),25000.0) -> 25000 | G25: =IFERROR(__xludf.DUMMYFUNCTION("""COMPUTED_VALUE"""),12500.0) -> 12500 | H25: =IFERROR(__xludf.DUMMYFUNCTION("""COMPUTED_VALUE"""),3.125E8) -> 312500000 | J25: =IFERROR(__xludf.DUMMYFUNCTION("""COMPUTED_VALUE""")," Solar ") -> Solar
A26: =IFERROR(__xludf.DUMMYFUNCTION("""COMPUTED_VALUE"""),15.0) -> 15 | B26: =IFERROR(__xludf.DUMMYFUNCTION("""COMPUTED_VALUE"""),"Pertalite") -> Pertalite | C26: =IFERROR(__xludf.DUMMYFUNCTION("""COMPUTED_VALUE"""),13.0) -> 13 | D26: =IFERROR(__xludf.DUMMYFUNCTION("""COMPUTED_VALUE"""),"M015") -> M015 | E26: =IFERROR(__xludf.DUMMYFUNCTION("""COMPUTED_VALUE"""),"Liter") -> Liter | F26: =IFERROR(__xludf.DUMMYFUNCTION("""COMPUTED_VALUE"""),8000.0) -> 8000 | G26: =IFERROR(__xludf.DUMMYFUNCTION("""COMPUTED_VALUE"""),10000.0) -> 10000 | H26: =IFERROR(__xludf.DUMMYFUNCTION("""COMPUTED_VALUE"""),8.0E7) -> 80000000 | J26: =IFERROR(__xludf.DUMMYFUNCTION("""COMPUTED_VALUE""")," Pertalite ") -> Pertalite
A27: =IFERROR(__xludf.DUMMYFUNCTION("""COMPUTED_VALUE"""),16.0) -> 16 | H27: =IFERROR(__xludf.DUMMYFUNCTION("""COMPUTED_VALUE"""),0.0) -> 0
A28: =IFERROR(__xludf.DUMMYFUNCTION("""COMPUTED_VALUE"""),17.0) -> 17 | H28: =IFERROR(__xludf.DUMMYFUNCTION("""COMPUTED_VALUE"""),0.0) -> 0
A29: =IFERROR(__xludf.DUMMYFUNCTION("""COMPUTED_VALUE"""),18.0) -> 18 | H29: =IFERROR(__xludf.DUMMYFUNCTION("""COMPUTED_VALUE"""),0.0) -> 0
A30: =IFERROR(__xludf.DUMMYFUNCTION("""COMPUTED_VALUE"""),19.0) -> 19 | H30: =IFERROR(__xludf.DUMMYFUNCTION("""COMPUTED_VALUE"""),0.0) -> 0
A31: =IFERROR(__xludf.DUMMYFUNCTION("""COMPUTED_VALUE"""),20.0) -> 20 | H31: =IFERROR(__xludf.DUMMYFUNCTION("""COMPUTED_VALUE"""),0.0) -> 0
A32: =IFERROR(__xludf.DUMMYFUNCTION("""COMPUTED_VALUE"""),21.0) -> 21 | H32: =IFERROR(__xludf.DUMMYFUNCTION("""COMPUTED_VALUE"""),0.0) -> 0
A33: =IFERROR(__xludf.DUMMYFUNCTION("""COMPUTED_VALUE"""),22.0) -> 22 | H33: =IFERROR(__xludf.DUMMYFUNCTION("""COMPUTED_VALUE"""),0.0) -> 0
A34: =IFERROR(__xludf.DUMMYFUNCTION("""COMPUTED_VALUE"""),23.0) -> 23 | H34: =IFERROR(__xludf.DUMMYFUNCTION("""COMPUTED_VALUE"""),0.0) -> 0
A35: =IFERROR(__xludf.DUMMYFUNCTION("""COMPUTED_VALUE"""),24.0) -> 24 | H35: =IFERROR(__xludf.DUMMYFUNCTION("""COMPUTED_VALUE"""),0.0) -> 0
A36: =IFERROR(__xludf.DUMMYFUNCTION("""COMPUTED_VALUE"""),25.0) -> 25 | H36: =IFERROR(__xludf.DUMMYFUNCTION("""COMPUTED_VALUE"""),0.0) -> 0
A37: =IFERROR(__xludf.DUMMYFUNCTION("""COMPUTED_VALUE"""),26.0) -> 26 | H37: =IFERROR(__xludf.DUMMYFUNCTION("""COMPUTED_VALUE"""),0.0) -> 0
A38: =IFERROR(__xludf.DUMMYFUNCTION("""COMPUTED_VALUE"""),27.0) -> 27 | H38: =IFERROR(__xludf.DUMMYFUNCTION("""COMPUTED_VALUE"""),0.0) -> 0
A39: =IFERROR(__xludf.DUMMYFUNCTION("""COMPUTED_VALUE"""),28.0) -> 28 | H39: =IFERROR(__xludf.DUMMYFUNCTION("""COMPUTED_VALUE"""),0.0) -> 0
A40: =IFERROR(__xludf.DUMMYFUNCTION("""COMPUTED_VALUE"""),29.0) -> 29 | H40: =IFERROR(__xludf.DUMMYFUNCTION("""COMPUTED_VALUE"""),0.0) -> 0
A41: =IFERROR(__xludf.DUMMYFUNCTION("""COMPUTED_VALUE"""),30.0) -> 30 | H41: =IFERROR(__xludf.DUMMYFUNCTION("""COMPUTED_VALUE"""),0.0) -> 0
A42: =IFERROR(__xludf.DUMMYFUNCTION("""COMPUTED_VALUE"""),31.0) -> 31 | H42: =IFERROR(__xludf.DUMMYFUNCTION("""COMPUTED_VALUE"""),0.0) -> 0
A43: =IFERROR(__xludf.DUMMYFUNCTION("""COMPUTED_VALUE"""),32.0) -> 32 | H43: =IFERROR(__xludf.DUMMYFUNCTION("""COMPUTED_VALUE"""),0.0) -> 0
A44: =IFERROR(__xludf.DUMMYFUNCTION("""COMPUTED_VALUE"""),33.0) -> 33 | H44: =IFERROR(__xludf.DUMMYFUNCTION("""COMPUTED_VALUE"""),0.0) -> 0
...

Sheet PO MTRL
B1: =IFERROR(__xludf.DUMMYFUNCTION("IMPORTRANGE(""https://docs.google.com/spreadsheets/d/1j-8kBYYPqmcXqtsp1nk42pAatSq0tHG-RvDmkOpWhbc/edit?gid=1519252238#gid=1519252238"",""PO MTRL!$B$1:$U"")"),"KONTROL PO MATERIAL") -> KONTROL PO MATERIAL | R1: =IFERROR(__xludf.DUMMYFUNCTION("""COMPUTED_VALUE""")," PERHATIAN : > ISI KOLOM WARNA KUNING > SHEET TANDA KUNCI SEBAGAI REFERENSI (Tdk bisa diedit, tapi bisa dicoppy) ") -> PERHATIAN : > ISI KOLOM WARNA KUNING > SHEET TANDA KUNCI SEBAGAI REFERENSI (Tdk bisa diedit, tapi bisa dicoppy)
G3: =IFERROR(__xludf.DUMMYFUNCTION("""COMPUTED_VALUE"""),"PIC: LOGISTIK DIVISI") -> PIC: LOGISTIK DIVISI | H3: =IFERROR(__xludf.DUMMYFUNCTION("""COMPUTED_VALUE"""),"T O T A L") -> T O T A L | L3: =IFERROR(__xludf.DUMMYFUNCTION("""COMPUTED_VALUE"""),1.58886E8) -> 158886000 | Q3: =IFERROR(__xludf.DUMMYFUNCTION("""COMPUTED_VALUE"""),2.86910225E9) -> 2869102250
B5: =IFERROR(__xludf.DUMMYFUNCTION("""COMPUTED_VALUE"""),"NOMOR") -> NOMOR | C5: =IFERROR(__xludf.DUMMYFUNCTION("""COMPUTED_VALUE"""),"NOMOR") -> NOMOR | D5: =IFERROR(__xludf.DUMMYFUNCTION("""COMPUTED_VALUE"""),"KODE") -> KODE | E5: =IFERROR(__xludf.DUMMYFUNCTION("""COMPUTED_VALUE"""),"KODE") -> KODE | F5: =IFERROR(__xludf.DUMMYFUNCTION("""COMPUTED_VALUE"""),"TANGGAL") -> TANGGAL | G5: =IFERROR(__xludf.DUMMYFUNCTION("""COMPUTED_VALUE"""),"JENIS MATERIAL") -> JENIS MATERIAL | H5: =IFERROR(__xludf.DUMMYFUNCTION("""COMPUTED_VALUE"""),"SATUAN") -> SATUAN | I5: =IFERROR(__xludf.DUMMYFUNCTION("""COMPUTED_VALUE"""),"HARSAT") -> HARSAT | J5: =IFERROR(__xludf.DUMMYFUNCTION("""COMPUTED_VALUE"""),"KUANTITAS PO") -> KUANTITAS PO | L5: =IFERROR(__xludf.DUMMYFUNCTION("""COMPUTED_VALUE"""),"JUMLAH HARGA PO") -> JUMLAH HARGA PO | N5: =IFERROR(__xludf.DUMMYFUNCTION("""COMPUTED_VALUE"""),"SUMDA (RAPL)") -> SUMDA (RAPL) | P5: =IFERROR(__xludf.DUMMYFUNCTION("""COMPUTED_VALUE"""),"SELISIH PO THD RAPL") -> SELISIH PO THD RAPL | R5: =IFERROR(__xludf.DUMMYFUNCTION("""COMPUTED_VALUE"""),"NAMA SUPLYER") -> NAMA SUPLYER | S5: =IFERROR(__xludf.DUMMYFUNCTION("""COMPUTED_VALUE"""),"KETERANGAN") -> KETERANGAN
B6: =IFERROR(__xludf.DUMMYFUNCTION("""COMPUTED_VALUE"""),"URUT PO") -> URUT PO | C6: =IFERROR(__xludf.DUMMYFUNCTION("""COMPUTED_VALUE"""),"PO") -> PO | D6: =IFERROR(__xludf.DUMMYFUNCTION("""COMPUTED_VALUE"""),"AKUN") -> AKUN | E6: =IFERROR(__xludf.DUMMYFUNCTION("""COMPUTED_VALUE"""),"MATERIAL") -> MATERIAL | I6: =IFERROR(__xludf.DUMMYFUNCTION("""COMPUTED_VALUE"""),"PO") -> PO | J6: =IFERROR(__xludf.DUMMYFUNCTION("""COMPUTED_VALUE"""),"SAAT INI") -> SAAT INI | K6: =IFERROR(__xludf.DUMMYFUNCTION("""COMPUTED_VALUE"""),"AKUM (DIV+PROY)") -> AKUM (DIV+PROY) | L6: =IFERROR(__xludf.DUMMYFUNCTION("""COMPUTED_VALUE"""),"SAAT INI") -> SAAT INI | M6: =IFERROR(__xludf.DUMMYFUNCTION("""COMPUTED_VALUE"""),"AKUM (DIV+PROY)") -> AKUM (DIV+PROY) | N6: =IFERROR(__xludf.DUMMYFUNCTION("""COMPUTED_VALUE"""),"KUANTITAS") -> KUANTITAS | O6: =IFERROR(__xludf.DUMMYFUNCTION("""COMPUTED_VALUE"""),"JMH HRG") -> JMH HRG | P6: =IFERROR(__xludf.DUMMYFUNCTION("""COMPUTED_VALUE"""),"KUANTITAS") -> KUANTITAS | Q6: =IFERROR(__xludf.DUMMYFUNCTION("""COMPUTED_VALUE"""),"JMH HRG") -> JMH HRG
B7: =IFERROR(__xludf.DUMMYFUNCTION("""COMPUTED_VALUE"""),"A") -> A | C7: =IFERROR(__xludf.DUMMYFUNCTION("""COMPUTED_VALUE"""),"B") -> B | D7: =IFERROR(__xludf.DUMMYFUNCTION("""COMPUTED_VALUE"""),"C") -> C | E7: =IFERROR(__xludf.DUMMYFUNCTION("""COMPUTED_VALUE"""),"D") -> D | F7: =IFERROR(__xludf.DUMMYFUNCTION("""COMPUTED_VALUE"""),"E") -> E | G7: =IFERROR(__xludf.DUMMYFUNCTION("""COMPUTED_VALUE"""),"F") -> F | H7: =IFERROR(__xludf.DUMMYFUNCTION("""COMPUTED_VALUE"""),"G") -> G | I7: =IFERROR(__xludf.DUMMYFUNCTION("""COMPUTED_VALUE"""),"H") -> H | J7: =IFERROR(__xludf.DUMMYFUNCTION("""COMPUTED_VALUE"""),"I") -> I | K7: =IFERROR(__xludf.DUMMYFUNCTION("""COMPUTED_VALUE"""),"J") -> J | L7: =IFERROR(__xludf.DUMMYFUNCTION("""COMPUTED_VALUE"""),"K= H x I") -> K= H x I | M7: =IFERROR(__xludf.DUMMYFUNCTION("""COMPUTED_VALUE"""),"L") -> L | N7: =IFERROR(__xludf.DUMMYFUNCTION("""COMPUTED_VALUE"""),"M") -> M | O7: =IFERROR(__xludf.DUMMYFUNCTION("""COMPUTED_VALUE"""),"N") -> N | P7: =IFERROR(__xludf.DUMMYFUNCTION("""COMPUTED_VALUE"""),"O= M - J") -> O= M - J | Q7: =IFERROR(__xludf.DUMMYFUNCTION("""COMPUTED_VALUE"""),"P= N - L") -> P= N - L | R7: =IFERROR(__xludf.DUMMYFUNCTION("""COMPUTED_VALUE"""),"Q") -> Q | S7: =IFERROR(__xludf.DUMMYFUNCTION("""COMPUTED_VALUE"""),"R") -> R | U7: =IFERROR(__xludf.DUMMYFUNCTION("""COMPUTED_VALUE"""),"CATATAN :") -> CATATAN :
U8: =IFERROR(__xludf.DUMMYFUNCTION("""COMPUTED_VALUE"""),"1. B511") -> 1. B511
B9: =IFERROR(__xludf.DUMMYFUNCTION("""COMPUTED_VALUE"""),1.0) -> 1 | C9: =IFERROR(__xludf.DUMMYFUNCTION("""COMPUTED_VALUE""")," PO1 ") -> PO1 | D9: =IFERROR(__xludf.DUMMYFUNCTION("""COMPUTED_VALUE"""),2.0) -> 2 | E9: =IFERROR(__xludf.DUMMYFUNCTION("""COMPUTED_VALUE""")," M002 ") -> M002 | F9: =IFERROR(__xludf.DUMMYFUNCTION("""COMPUTED_VALUE"""),46154.0) -> 46154 | G9: =IFERROR(__xludf.DUMMYFUNCTION("""COMPUTED_VALUE""")," Baja Tul Ulir ") -> Baja Tul Ulir | H9: =IFERROR(__xludf.DUMMYFUNCTION("""COMPUTED_VALUE""")," KG ") -> KG | I9: =IFERROR(__xludf.DUMMYFUNCTION("""COMPUTED_VALUE"""),8500.0) -> 8500 | J9: =IFERROR(__xludf.DUMMYFUNCTION("""COMPUTED_VALUE"""),5000.0) -> 5000 | K9: =IFERROR(__xludf.DUMMYFUNCTION("""COMPUTED_VALUE"""),7000.0) -> 7000 | L9: =IFERROR(__xludf.DUMMYFUNCTION("""COMPUTED_VALUE"""),4.25E7) -> 42500000 | M9: =IFERROR(__xludf.DUMMYFUNCTION("""COMPUTED_VALUE"""),6.05E7) -> 60500000 | N9: =IFERROR(__xludf.DUMMYFUNCTION("""COMPUTED_VALUE"""),146156.25) -> 146156.25 | O9: =IFERROR(__xludf.DUMMYFUNCTION("""COMPUTED_VALUE"""),1.242328125E9) -> 1242328125 | P9: =IFERROR(__xludf.DUMMYFUNCTION("""COMPUTED_VALUE"""),139156.25) -> 139156.25 | Q9: =IFERROR(__xludf.DUMMYFUNCTION("""COMPUTED_VALUE"""),1.181828125E9) -> 1181828125 | R9: =IFERROR(__xludf.DUMMYFUNCTION("""COMPUTED_VALUE"""),"KKK") -> KKK | S9: =IFERROR(__xludf.DUMMYFUNCTION("""COMPUTED_VALUE"""),"XXX") -> XXX
B10: =IFERROR(__xludf.DUMMYFUNCTION("""COMPUTED_VALUE"""),2.0) -> 2 | C10: =IFERROR(__xludf.DUMMYFUNCTION("""COMPUTED_VALUE""")," PO2 ") -> PO2 | D10: =IFERROR(__xludf.DUMMYFUNCTION("""COMPUTED_VALUE"""),2.0) -> 2 | E10: =IFERROR(__xludf.DUMMYFUNCTION("""COMPUTED_VALUE""")," M002 ") -> M002 | F10: =IFERROR(__xludf.DUMMYFUNCTION("""COMPUTED_VALUE"""),46157.0) -> 46157 | G10: =IFERROR(__xludf.DUMMYFUNCTION("""COMPUTED_VALUE""")," Baja Tul Ulir ") -> Baja Tul Ulir | H10: =IFERROR(__xludf.DUMMYFUNCTION("""COMPUTED_VALUE""")," KG ") -> KG | I10: =IFERROR(__xludf.DUMMYFUNCTION("""COMPUTED_VALUE"""),9000.0) -> 9000 | J10: =IFERROR(__xludf.DUMMYFUNCTION("""COMPUTED_VALUE"""),2000.0) -> 2000 | K10: =IFERROR(__xludf.DUMMYFUNCTION("""COMPUTED_VALUE"""),7000.0) -> 7000 | L10: =IFERROR(__xludf.DUMMYFUNCTION("""COMPUTED_VALUE"""),1.8E7) -> 18000000 | M10: =IFERROR(__xludf.DUMMYFUNCTION("""COMPUTED_VALUE"""),6.05E7) -> 60500000 | N10: =IFERROR(__xludf.DUMMYFUNCTION("""COMPUTED_VALUE"""),146156.25) -> 146156.25 | O10: =IFERROR(__xludf.DUMMYFUNCTION("""COMPUTED_VALUE"""),1.242328125E9) -> 1242328125 | P10: =IFERROR(__xludf.DUMMYFUNCTION("""COMPUTED_VALUE"""),139156.25) -> 139156.25 | Q10: =IFERROR(__xludf.DUMMYFUNCTION("""COMPUTED_VALUE"""),1.181828125E9) -> 1181828125 | R10: =IFERROR(__xludf.DUMMYFUNCTION("""COMPUTED_VALUE"""),"LLL") -> LLL | S10: =IFERROR(__xludf.DUMMYFUNCTION("""COMPUTED_VALUE"""),"XXX") -> XXX
B11: =IFERROR(__xludf.DUMMYFUNCTION("""COMPUTED_VALUE"""),3.0) -> 3 | D11: =IFERROR(__xludf.DUMMYFUNCTION("""COMPUTED_VALUE"""),"") | E11: =IFERROR(__xludf.DUMMYFUNCTION("""COMPUTED_VALUE"""),0.0) -> 0 | H11: =IFERROR(__xludf.DUMMYFUNCTION("""COMPUTED_VALUE"""),0.0) -> 0 | K11: =IFERROR(__xludf.DUMMYFUNCTION("""COMPUTED_VALUE"""),0.0) -> 0 | L11: =IFERROR(__xludf.DUMMYFUNCTION("""COMPUTED_VALUE"""),0.0) -> 0 | M11: =IFERROR(__xludf.DUMMYFUNCTION("""COMPUTED_VALUE"""),0.0) -> 0 | N11: =IFERROR(__xludf.DUMMYFUNCTION("""COMPUTED_VALUE"""),0.0) -> 0 | O11: =IFERROR(__xludf.DUMMYFUNCTION("""COMPUTED_VALUE"""),0.0) -> 0 | P11: =IFERROR(__xludf.DUMMYFUNCTION("""COMPUTED_VALUE"""),0.0) -> 0 | Q11: =IFERROR(__xludf.DUMMYFUNCTION("""COMPUTED_VALUE"""),0.0) -> 0
B12: =IFERROR(__xludf.DUMMYFUNCTION("""COMPUTED_VALUE"""),4.0) -> 4 | C12: =IFERROR(__xludf.DUMMYFUNCTION("""COMPUTED_VALUE""")," PO3 ") -> PO3 | D12: =IFERROR(__xludf.DUMMYFUNCTION("""COMPUTED_VALUE"""),7.0) -> 7 | E12: =IFERROR(__xludf.DUMMYFUNCTION("""COMPUTED_VALUE""")," M007 ") -> M007 | F12: =IFERROR(__xludf.DUMMYFUNCTION("""COMPUTED_VALUE"""),46158.0) -> 46158 | G12: =IFERROR(__xludf.DUMMYFUNCTION("""COMPUTED_VALUE""")," Multipleks 18 mm ") -> Multipleks 18 mm | H12: =IFERROR(__xludf.DUMMYFUNCTION("""COMPUTED_VALUE""")," LBR ") -> LBR | I12: =IFERROR(__xludf.DUMMYFUNCTION("""COMPUTED_VALUE"""),250000.0) -> 250000 | J12: =IFERROR(__xludf.DUMMYFUNCTION("""COMPUTED_VALUE"""),10.0) -> 10 | K12: =IFERROR(__xludf.DUMMYFUNCTION("""COMPUTED_VALUE"""),10.0) -> 10 | L12: =IFERROR(__xludf.DUMMYFUNCTION("""COMPUTED_VALUE"""),2500000.0) -> 2500000 | M12: =IFERROR(__xludf.DUMMYFUNCTION("""COMPUTED_VALUE"""),2500000.0) -> 2500000 | N12: =IFERROR(__xludf.DUMMYFUNCTION("""COMPUTED_VALUE"""),60.0) -> 60 | O12: =IFERROR(__xludf.DUMMYFUNCTION("""COMPUTED_VALUE"""),1.5E7) -> 15000000 | P12: =IFERROR(__xludf.DUMMYFUNCTION("""COMPUTED_VALUE"""),50.0) -> 50 | Q12: =IFERROR(__xludf.DUMMYFUNCTION("""COMPUTED_VALUE"""),1.25E7) -> 12500000 | R12: =IFERROR(__xludf.DUMMYFUNCTION("""COMPUTED_VALUE"""),"GGG") -> GGG | S12: =IFERROR(__xludf.DUMMYFUNCTION("""COMPUTED_VALUE"""),"XXX") -> XXX
B13: =IFERROR(__xludf.DUMMYFUNCTION("""COMPUTED_VALUE"""),5.0) -> 5 | C13: =IFERROR(__xludf.DUMMYFUNCTION("""COMPUTED_VALUE""")," PO3 ") -> PO3 | D13: =IFERROR(__xludf.DUMMYFUNCTION("""COMPUTED_VALUE"""),8.0) -> 8 | E13: =IFERROR(__xludf.DUMMYFUNCTION("""COMPUTED_VALUE""")," M008 ") -> M008 | F13: =IFERROR(__xludf.DUMMYFUNCTION("""COMPUTED_VALUE"""),46158.0) -> 46158 | G13: =IFERROR(__xludf.DUMMYFUNCTION("""COMPUTED_VALUE""")," Paku ") -> Paku | H13: =IFERROR(__xludf.DUMMYFUNCTION("""COMPUTED_VALUE""")," KG ") -> KG | I13: =IFERROR(__xludf.DUMMYFUNCTION("""COMPUTED_VALUE"""),20000.0) -> 20000 | J13: =IFERROR(__xludf.DUMMYFUNCTION("""COMPUTED_VALUE"""),8.0) -> 8 | K13: =IFERROR(__xludf.DUMMYFUNCTION("""COMPUTED_VALUE"""),10.0) -> 10 | L13: =IFERROR(__xludf.DUMMYFUNCTION("""COMPUTED_VALUE"""),160000.0) -> 160000 | M13: =IFERROR(__xludf.DUMMYFUNCTION("""COMPUTED_VALUE"""),202000.0) -> 202000 | N13: =IFERROR(__xludf.DUMMYFUNCTION("""COMPUTED_VALUE"""),30.0) -> 30 | O13: =IFERROR(__xludf.DUMMYFUNCTION("""COMPUTED_VALUE"""),600000.0) -> 600000 | P13: =IFERROR(__xludf.DUMMYFUNCTION("""COMPUTED_VALUE"""),20.0) -> 20 | Q13: =IFERROR(__xludf.DUMMYFUNCTION("""COMPUTED_VALUE"""),398000.0) -> 398000 | R13: =IFERROR(__xludf.DUMMYFUNCTION("""COMPUTED_VALUE"""),"GGG") -> GGG | S13: =IFERROR(__xludf.DUMMYFUNCTION("""COMPUTED_VALUE"""),"XXX") -> XXX
B14: =IFERROR(__xludf.DUMMYFUNCTION("""COMPUTED_VALUE"""),6.0) -> 6 | D14: =IFERROR(__xludf.DUMMYFUNCTION("""COMPUTED_VALUE"""),"") | E14: =IFERROR(__xludf.DUMMYFUNCTION("""COMPUTED_VALUE"""),0.0) -> 0 | H14: =IFERROR(__xludf.DUMMYFUNCTION("""COMPUTED_VALUE"""),0.0) -> 0 | K14: =IFERROR(__xludf.DUMMYFUNCTION("""COMPUTED_VALUE"""),0.0) -> 0 | L14: =IFERROR(__xludf.DUMMYFUNCTION("""COMPUTED_VALUE"""),0.0) -> 0 | M14: =IFERROR(__xludf.DUMMYFUNCTION("""COMPUTED_VALUE"""),0.0) -> 0 | N14: =IFERROR(__xludf.DUMMYFUNCTION("""COMPUTED_VALUE"""),0.0) -> 0 | O14: =IFERROR(__xludf.DUMMYFUNCTION("""COMPUTED_VALUE"""),0.0) -> 0 | P14: =IFERROR(__xludf.DUMMYFUNCTION("""COMPUTED_VALUE"""),0.0) -> 0 | Q14: =IFERROR(__xludf.DUMMYFUNCTION("""COMPUTED_VALUE"""),0.0) -> 0
B15: =IFERROR(__xludf.DUMMYFUNCTION("""COMPUTED_VALUE"""),7.0) -> 7 | C15: =IFERROR(__xludf.DUMMYFUNCTION("""COMPUTED_VALUE""")," PO4 ") -> PO4 | D15: =IFERROR(__xludf.DUMMYFUNCTION("""COMPUTED_VALUE"""),3.0) -> 3 | E15: =IFERROR(__xludf.DUMMYFUNCTION("""COMPUTED_VALUE""")," M003 ") -> M003 | F15: =IFERROR(__xludf.DUMMYFUNCTION("""COMPUTED_VALUE"""),46160.0) -> 46160 | G15: =IFERROR(__xludf.DUMMYFUNCTION("""COMPUTED_VALUE""")," Beton Ready fc' 30 MPa ") -> Beton Ready fc' 30 MPa | H15: =IFERROR(__xludf.DUMMYFUNCTION("""COMPUTED_VALUE""")," M3 ") -> M3 | I15: =IFERROR(__xludf.DUMMYFUNCTION("""COMPUTED_VALUE"""),200000.0) -> 200000 | J15: =IFERROR(__xludf.DUMMYFUNCTION("""COMPUTED_VALUE"""),25.0) -> 25 | K15: =IFERROR(__xludf.DUMMYFUNCTION("""COMPUTED_VALUE"""),25.0) -> 25 | L15: =IFERROR(__xludf.DUMMYFUNCTION("""COMPUTED_VALUE"""),5000000.0) -> 5000000 | M15: =IFERROR(__xludf.DUMMYFUNCTION("""COMPUTED_VALUE"""),5000000.0) -> 5000000 | N15: =IFERROR(__xludf.DUMMYFUNCTION("""COMPUTED_VALUE"""),474.375) -> 474.375 | O15: =IFERROR(__xludf.DUMMYFUNCTION("""COMPUTED_VALUE"""),4.9335E8) -> 493350000 | P15: =IFERROR(__xludf.DUMMYFUNCTION("""COMPUTED_VALUE"""),449.375) -> 449.375 | Q15: =IFERROR(__xludf.DUMMYFUNCTION("""COMPUTED_VALUE"""),4.8835E8) -> 488350000 | R15: =IFERROR(__xludf.DUMMYFUNCTION("""COMPUTED_VALUE"""),"JJJ") -> JJJ | S15: =IFERROR(__xludf.DUMMYFUNCTION("""COMPUTED_VALUE"""),"XXX") -> XXX
B16: =IFERROR(__xludf.DUMMYFUNCTION("""COMPUTED_VALUE"""),8.0) -> 8 | D16: =IFERROR(__xludf.DUMMYFUNCTION("""COMPUTED_VALUE"""),"") | E16: =IFERROR(__xludf.DUMMYFUNCTION("""COMPUTED_VALUE"""),0.0) -> 0 | H16: =IFERROR(__xludf.DUMMYFUNCTION("""COMPUTED_VALUE"""),0.0) -> 0 | K16: =IFERROR(__xludf.DUMMYFUNCTION("""COMPUTED_VALUE"""),0.0) -> 0 | L16: =IFERROR(__xludf.DUMMYFUNCTION("""COMPUTED_VALUE"""),0.0) -> 0 | M16: =IFERROR(__xludf.DUMMYFUNCTION("""COMPUTED_VALUE"""),0.0) -> 0 | N16: =IFERROR(__xludf.DUMMYFUNCTION("""COMPUTED_VALUE"""),0.0) -> 0 | O16: =IFERROR(__xludf.DUMMYFUNCTION("""COMPUTED_VALUE"""),0.0) -> 0 | P16: =IFERROR(__xludf.DUMMYFUNCTION("""COMPUTED_VALUE"""),0.0) -> 0 | Q16: =IFERROR(__xludf.DUMMYFUNCTION("""COMPUTED_VALUE"""),0.0) -> 0
B17: =IFERROR(__xludf.DUMMYFUNCTION("""COMPUTED_VALUE"""),9.0) -> 9 | D17: =IFERROR(__xludf.DUMMYFUNCTION("""COMPUTED_VALUE"""),"") | E17: =IFERROR(__xludf.DUMMYFUNCTION("""COMPUTED_VALUE"""),0.0) -> 0 | H17: =IFERROR(__xludf.DUMMYFUNCTION("""COMPUTED_VALUE"""),0.0) -> 0 | K17: =IFERROR(__xludf.DUMMYFUNCTION("""COMPUTED_VALUE"""),0.0) -> 0 | L17: =IFERROR(__xludf.DUMMYFUNCTION("""COMPUTED_VALUE"""),0.0) -> 0 | M17: =IFERROR(__xludf.DUMMYFUNCTION("""COMPUTED_VALUE"""),0.0) -> 0 | N17: =IFERROR(__xludf.DUMMYFUNCTION("""COMPUTED_VALUE"""),0.0) -> 0 | O17: =IFERROR(__xludf.DUMMYFUNCTION("""COMPUTED_VALUE"""),0.0) -> 0 | P17: =IFERROR(__xludf.DUMMYFUNCTION("""COMPUTED_VALUE"""),0.0) -> 0 | Q17: =IFERROR(__xludf.DUMMYFUNCTION("""COMPUTED_VALUE"""),0.0) -> 0
B18: =IFERROR(__xludf.DUMMYFUNCTION("""COMPUTED_VALUE"""),10.0) -> 10 | D18: =IFERROR(__xludf.DUMMYFUNCTION("""COMPUTED_VALUE"""),"") | E18: =IFERROR(__xludf.DUMMYFUNCTION("""COMPUTED_VALUE"""),0.0) -> 0 | H18: =IFERROR(__xludf.DUMMYFUNCTION("""COMPUTED_VALUE"""),0.0) -> 0 | K18: =IFERROR(__xludf.DUMMYFUNCTION("""COMPUTED_VALUE"""),0.0) -> 0 | L18: =IFERROR(__xludf.DUMMYFUNCTION("""COMPUTED_VALUE"""),0.0) -> 0 | M18: =IFERROR(__xludf.DUMMYFUNCTION("""COMPUTED_VALUE"""),0.0) -> 0 | N18: =IFERROR(__xludf.DUMMYFUNCTION("""COMPUTED_VALUE"""),0.0) -> 0 | O18: =IFERROR(__xludf.DUMMYFUNCTION("""COMPUTED_VALUE"""),0.0) -> 0 | P18: =IFERROR(__xludf.DUMMYFUNCTION("""COMPUTED_VALUE"""),0.0) -> 0 | Q18: =IFERROR(__xludf.DUMMYFUNCTION("""COMPUTED_VALUE"""),0.0) -> 0
B19: =IFERROR(__xludf.DUMMYFUNCTION("""COMPUTED_VALUE"""),11.0) -> 11 | D19: =IFERROR(__xludf.DUMMYFUNCTION("""COMPUTED_VALUE"""),"") | E19: =IFERROR(__xludf.DUMMYFUNCTION("""COMPUTED_VALUE"""),0.0) -> 0 | H19: =IFERROR(__xludf.DUMMYFUNCTION("""COMPUTED_VALUE"""),0.0) -> 0 | K19: =IFERROR(__xludf.DUMMYFUNCTION("""COMPUTED_VALUE"""),0.0) -> 0 | L19: =IFERROR(__xludf.DUMMYFUNCTION("""COMPUTED_VALUE"""),0.0) -> 0 | M19: =IFERROR(__xludf.DUMMYFUNCTION("""COMPUTED_VALUE"""),0.0) -> 0 | N19: =IFERROR(__xludf.DUMMYFUNCTION("""COMPUTED_VALUE"""),0.0) -> 0 | O19: =IFERROR(__xludf.DUMMYFUNCTION("""COMPUTED_VALUE"""),0.0) -> 0 | P19: =IFERROR(__xludf.DUMMYFUNCTION("""COMPUTED_VALUE"""),0.0) -> 0 | Q19: =IFERROR(__xludf.DUMMYFUNCTION("""COMPUTED_VALUE"""),0.0) -> 0
B20: =IFERROR(__xludf.DUMMYFUNCTION("""COMPUTED_VALUE"""),12.0) -> 12 | D20: =IFERROR(__xludf.DUMMYFUNCTION("""COMPUTED_VALUE"""),"") | E20: =IFERROR(__xludf.DUMMYFUNCTION("""COMPUTED_VALUE"""),0.0) -> 0 | H20: =IFERROR(__xludf.DUMMYFUNCTION("""COMPUTED_VALUE"""),0.0) -> 0 | K20: =IFERROR(__xludf.DUMMYFUNCTION("""COMPUTED_VALUE"""),0.0) -> 0 | L20: =IFERROR(__xludf.DUMMYFUNCTION("""COMPUTED_VALUE"""),0.0) -> 0 | M20: =IFERROR(__xludf.DUMMYFUNCTION("""COMPUTED_VALUE"""),0.0) -> 0 | N20: =IFERROR(__xludf.DUMMYFUNCTION("""COMPUTED_VALUE"""),0.0) -> 0 | O20: =IFERROR(__xludf.DUMMYFUNCTION("""COMPUTED_VALUE"""),0.0) -> 0 | P20: =IFERROR(__xludf.DUMMYFUNCTION("""COMPUTED_VALUE"""),0.0) -> 0 | Q20: =IFERROR(__xludf.DUMMYFUNCTION("""COMPUTED_VALUE"""),0.0) -> 0
B21: =IFERROR(__xludf.DUMMYFUNCTION("""COMPUTED_VALUE"""),13.0) -> 13 | D21: =IFERROR(__xludf.DUMMYFUNCTION("""COMPUTED_VALUE"""),"") | E21: =IFERROR(__xludf.DUMMYFUNCTION("""COMPUTED_VALUE"""),0.0) -> 0 | H21: =IFERROR(__xludf.DUMMYFUNCTION("""COMPUTED_VALUE"""),0.0) -> 0 | K21: =IFERROR(__xludf.DUMMYFUNCTION("""COMPUTED_VALUE"""),0.0) -> 0 | L21: =IFERROR(__xludf.DUMMYFUNCTION("""COMPUTED_VALUE"""),0.0) -> 0 | M21: =IFERROR(__xludf.DUMMYFUNCTION("""COMPUTED_VALUE"""),0.0) -> 0 | N21: =IFERROR(__xludf.DUMMYFUNCTION("""COMPUTED_VALUE"""),0.0) -> 0 | O21: =IFERROR(__xludf.DUMMYFUNCTION("""COMPUTED_VALUE"""),0.0) -> 0 | P21: =IFERROR(__xludf.DUMMYFUNCTION("""COMPUTED_VALUE"""),0.0) -> 0 | Q21: =IFERROR(__xludf.DUMMYFUNCTION("""COMPUTED_VALUE"""),0.0) -> 0
B22: =IFERROR(__xludf.DUMMYFUNCTION("""COMPUTED_VALUE"""),14.0) -> 14 | D22: =IFERROR(__xludf.DUMMYFUNCTION("""COMPUTED_VALUE"""),"") | E22: =IFERROR(__xludf.DUMMYFUNCTION("""COMPUTED_VALUE"""),0.0) -> 0 | H22: =IFERROR(__xludf.DUMMYFUNCTION("""COMPUTED_VALUE"""),0.0) -> 0 | K22: =IFERROR(__xludf.DUMMYFUNCTION("""COMPUTED_VALUE"""),0.0) -> 0 | L22: =IFERROR(__xludf.DUMMYFUNCTION("""COMPUTED_VALUE"""),0.0) -> 0 | M22: =IFERROR(__xludf.DUMMYFUNCTION("""COMPUTED_VALUE"""),0.0) -> 0 | N22: =IFERROR(__xludf.DUMMYFUNCTION("""COMPUTED_VALUE"""),0.0) -> 0 | O22: =IFERROR(__xludf.DUMMYFUNCTION("""COMPUTED_VALUE"""),0.0) -> 0 | P22: =IFERROR(__xludf.DUMMYFUNCTION("""COMPUTED_VALUE"""),0.0) -> 0 | Q22: =IFERROR(__xludf.DUMMYFUNCTION("""COMPUTED_VALUE"""),0.0) -> 0
B23: =IFERROR(__xludf.DUMMYFUNCTION("""COMPUTED_VALUE"""),15.0) -> 15 | D23: =IFERROR(__xludf.DUMMYFUNCTION("""COMPUTED_VALUE"""),"") | E23: =IFERROR(__xludf.DUMMYFUNCTION("""COMPUTED_VALUE"""),0.0) -> 0 | H23: =IFERROR(__xludf.DUMMYFUNCTION("""COMPUTED_VALUE"""),0.0) -> 0 | K23: =IFERROR(__xludf.DUMMYFUNCTION("""COMPUTED_VALUE"""),0.0) -> 0 | L23: =IFERROR(__xludf.DUMMYFUNCTION("""COMPUTED_VALUE"""),0.0) -> 0 | M23: =IFERROR(__xludf.DUMMYFUNCTION("""COMPUTED_VALUE"""),0.0) -> 0 | N23: =IFERROR(__xludf.DUMMYFUNCTION("""COMPUTED_VALUE"""),0.0) -> 0 | O23: =IFERROR(__xludf.DUMMYFUNCTION("""COMPUTED_VALUE"""),0.0) -> 0 | P23: =IFERROR(__xludf.DUMMYFUNCTION("""COMPUTED_VALUE"""),0.0) -> 0 | Q23: =IFERROR(__xludf.DUMMYFUNCTION("""COMPUTED_VALUE"""),0.0) -> 0
B24: =IFERROR(__xludf.DUMMYFUNCTION("""COMPUTED_VALUE"""),16.0) -> 16 | D24: =IFERROR(__xludf.DUMMYFUNCTION("""COMPUTED_VALUE"""),"") | E24: =IFERROR(__xludf.DUMMYFUNCTION("""COMPUTED_VALUE"""),0.0) -> 0 | H24: =IFERROR(__xludf.DUMMYFUNCTION("""COMPUTED_VALUE"""),0.0) -> 0 | K24: =IFERROR(__xludf.DUMMYFUNCTION("""COMPUTED_VALUE"""),0.0) -> 0 | L24: =IFERROR(__xludf.DUMMYFUNCTION("""COMPUTED_VALUE"""),0.0) -> 0 | M24: =IFERROR(__xludf.DUMMYFUNCTION("""COMPUTED_VALUE"""),0.0) -> 0 | N24: =IFERROR(__xludf.DUMMYFUNCTION("""COMPUTED_VALUE"""),0.0) -> 0 | O24: =IFERROR(__xludf.DUMMYFUNCTION("""COMPUTED_VALUE"""),0.0) -> 0 | P24: =IFERROR(__xludf.DUMMYFUNCTION("""COMPUTED_VALUE"""),0.0) -> 0 | Q24: =IFERROR(__xludf.DUMMYFUNCTION("""COMPUTED_VALUE"""),0.0) -> 0
B25: =IFERROR(__xludf.DUMMYFUNCTION("""COMPUTED_VALUE"""),17.0) -> 17 | D25: =IFERROR(__xludf.DUMMYFUNCTION("""COMPUTED_VALUE"""),"") | E25: =IFERROR(__xludf.DUMMYFUNCTION("""COMPUTED_VALUE"""),0.0) -> 0 | H25: =IFERROR(__xludf.DUMMYFUNCTION("""COMPUTED_VALUE"""),0.0) -> 0 | K25: =IFERROR(__xludf.DUMMYFUNCTION("""COMPUTED_VALUE"""),0.0) -> 0 | L25: =IFERROR(__xludf.DUMMYFUNCTION("""COMPUTED_VALUE"""),0.0) -> 0 | M25: =IFERROR(__xludf.DUMMYFUNCTION("""COMPUTED_VALUE"""),0.0) -> 0 | N25: =IFERROR(__xludf.DUMMYFUNCTION("""COMPUTED_VALUE"""),0.0) -> 0 | O25: =IFERROR(__xludf.DUMMYFUNCTION("""COMPUTED_VALUE"""),0.0) -> 0 | P25: =IFERROR(__xludf.DUMMYFUNCTION("""COMPUTED_VALUE"""),0.0) -> 0 | Q25: =IFERROR(__xludf.DUMMYFUNCTION("""COMPUTED_VALUE"""),0.0) -> 0
B26: =IFERROR(__xludf.DUMMYFUNCTION("""COMPUTED_VALUE"""),18.0) -> 18 | D26: =IFERROR(__xludf.DUMMYFUNCTION("""COMPUTED_VALUE"""),"") | E26: =IFERROR(__xludf.DUMMYFUNCTION("""COMPUTED_VALUE"""),0.0) -> 0 | H26: =IFERROR(__xludf.DUMMYFUNCTION("""COMPUTED_VALUE"""),0.0) -> 0 | K26: =IFERROR(__xludf.DUMMYFUNCTION("""COMPUTED_VALUE"""),0.0) -> 0 | L26: =IFERROR(__xludf.DUMMYFUNCTION("""COMPUTED_VALUE"""),0.0) -> 0 | M26: =IFERROR(__xludf.DUMMYFUNCTION("""COMPUTED_VALUE"""),0.0) -> 0 | N26: =IFERROR(__xludf.DUMMYFUNCTION("""COMPUTED_VALUE"""),0.0) -> 0 | O26: =IFERROR(__xludf.DUMMYFUNCTION("""COMPUTED_VALUE"""),0.0) -> 0 | P26: =IFERROR(__xludf.DUMMYFUNCTION("""COMPUTED_VALUE"""),0.0) -> 0 | Q26: =IFERROR(__xludf.DUMMYFUNCTION("""COMPUTED_VALUE"""),0.0) -> 0
B27: =IFERROR(__xludf.DUMMYFUNCTION("""COMPUTED_VALUE"""),19.0) -> 19 | D27: =IFERROR(__xludf.DUMMYFUNCTION("""COMPUTED_VALUE"""),"") | E27: =IFERROR(__xludf.DUMMYFUNCTION("""COMPUTED_VALUE"""),0.0) -> 0 | H27: =IFERROR(__xludf.DUMMYFUNCTION("""COMPUTED_VALUE"""),0.0) -> 0 | K27: =IFERROR(__xludf.DUMMYFUNCTION("""COMPUTED_VALUE"""),0.0) -> 0 | L27: =IFERROR(__xludf.DUMMYFUNCTION("""COMPUTED_VALUE"""),0.0) -> 0 | M27: =IFERROR(__xludf.DUMMYFUNCTION("""COMPUTED_VALUE"""),0.0) -> 0 | N27: =IFERROR(__xludf.DUMMYFUNCTION("""COMPUTED_VALUE"""),0.0) -> 0 | O27: =IFERROR(__xludf.DUMMYFUNCTION("""COMPUTED_VALUE"""),0.0) -> 0 | P27: =IFERROR(__xludf.DUMMYFUNCTION("""COMPUTED_VALUE"""),0.0) -> 0 | Q27: =IFERROR(__xludf.DUMMYFUNCTION("""COMPUTED_VALUE"""),0.0) -> 0
B28: =IFERROR(__xludf.DUMMYFUNCTION("""COMPUTED_VALUE"""),20.0) -> 20 | D28: =IFERROR(__xludf.DUMMYFUNCTION("""COMPUTED_VALUE"""),"") | E28: =IFERROR(__xludf.DUMMYFUNCTION("""COMPUTED_VALUE"""),0.0) -> 0 | H28: =IFERROR(__xludf.DUMMYFUNCTION("""COMPUTED_VALUE"""),0.0) -> 0 | K28: =IFERROR(__xludf.DUMMYFUNCTION("""COMPUTED_VALUE"""),0.0) -> 0 | L28: =IFERROR(__xludf.DUMMYFUNCTION("""COMPUTED_VALUE"""),0.0) -> 0 | M28: =IFERROR(__xludf.DUMMYFUNCTION("""COMPUTED_VALUE"""),0.0) -> 0 | N28: =IFERROR(__xludf.DUMMYFUNCTION("""COMPUTED_VALUE"""),0.0) -> 0 | O28: =IFERROR(__xludf.DUMMYFUNCTION("""COMPUTED_VALUE"""),0.0) -> 0 | P28: =IFERROR(__xludf.DUMMYFUNCTION("""COMPUTED_VALUE"""),0.0) -> 0 | Q28: =IFERROR(__xludf.DUMMYFUNCTION("""COMPUTED_VALUE"""),0.0) -> 0
B29: =IFERROR(__xludf.DUMMYFUNCTION("""COMPUTED_VALUE"""),21.0) -> 21 | D29: =IFERROR(__xludf.DUMMYFUNCTION("""COMPUTED_VALUE"""),"") | E29: =IFERROR(__xludf.DUMMYFUNCTION("""COMPUTED_VALUE"""),0.0) -> 0 | H29: =IFERROR(__xludf.DUMMYFUNCTION("""COMPUTED_VALUE"""),0.0) -> 0 | K29: =IFERROR(__xludf.DUMMYFUNCTION("""COMPUTED_VALUE"""),0.0) -> 0 | L29: =IFERROR(__xludf.DUMMYFUNCTION("""COMPUTED_VALUE"""),0.0) -> 0 | M29: =IFERROR(__xludf.DUMMYFUNCTION("""COMPUTED_VALUE"""),0.0) -> 0 | N29: =IFERROR(__xludf.DUMMYFUNCTION("""COMPUTED_VALUE"""),0.0) -> 0 | O29: =IFERROR(__xludf.DUMMYFUNCTION("""COMPUTED_VALUE"""),0.0) -> 0 | P29: =IFERROR(__xludf.DUMMYFUNCTION("""COMPUTED_VALUE"""),0.0) -> 0 | Q29: =IFERROR(__xludf.DUMMYFUNCTION("""COMPUTED_VALUE"""),0.0) -> 0
B30: =IFERROR(__xludf.DUMMYFUNCTION("""COMPUTED_VALUE"""),22.0) -> 22 | D30: =IFERROR(__xludf.DUMMYFUNCTION("""COMPUTED_VALUE"""),"") | E30: =IFERROR(__xludf.DUMMYFUNCTION("""COMPUTED_VALUE"""),0.0) -> 0 | H30: =IFERROR(__xludf.DUMMYFUNCTION("""COMPUTED_VALUE"""),0.0) -> 0 | K30: =IFERROR(__xludf.DUMMYFUNCTION("""COMPUTED_VALUE"""),0.0) -> 0 | L30: =IFERROR(__xludf.DUMMYFUNCTION("""COMPUTED_VALUE"""),0.0) -> 0 | M30: =IFERROR(__xludf.DUMMYFUNCTION("""COMPUTED_VALUE"""),0.0) -> 0 | N30: =IFERROR(__xludf.DUMMYFUNCTION("""COMPUTED_VALUE"""),0.0) -> 0 | O30: =IFERROR(__xludf.DUMMYFUNCTION("""COMPUTED_VALUE"""),0.0) -> 0 | P30: =IFERROR(__xludf.DUMMYFUNCTION("""COMPUTED_VALUE"""),0.0) -> 0 | Q30: =IFERROR(__xludf.DUMMYFUNCTION("""COMPUTED_VALUE"""),0.0) -> 0
B31: =IFERROR(__xludf.DUMMYFUNCTION("""COMPUTED_VALUE"""),23.0) -> 23 | D31: =IFERROR(__xludf.DUMMYFUNCTION("""COMPUTED_VALUE"""),"") | E31: =IFERROR(__xludf.DUMMYFUNCTION("""COMPUTED_VALUE"""),0.0) -> 0 | H31: =IFERROR(__xludf.DUMMYFUNCTION("""COMPUTED_VALUE"""),0.0) -> 0 | K31: =IFERROR(__xludf.DUMMYFUNCTION("""COMPUTED_VALUE"""),0.0) -> 0 | L31: =IFERROR(__xludf.DUMMYFUNCTION("""COMPUTED_VALUE"""),0.0) -> 0 | M31: =IFERROR(__xludf.DUMMYFUNCTION("""COMPUTED_VALUE"""),0.0) -> 0 | N31: =IFERROR(__xludf.DUMMYFUNCTION("""COMPUTED_VALUE"""),0.0) -> 0 | O31: =IFERROR(__xludf.DUMMYFUNCTION("""COMPUTED_VALUE"""),0.0) -> 0 | P31: =IFERROR(__xludf.DUMMYFUNCTION("""COMPUTED_VALUE"""),0.0) -> 0 | Q31: =IFERROR(__xludf.DUMMYFUNCTION("""COMPUTED_VALUE"""),0.0) -> 0
B32: =IFERROR(__xludf.DUMMYFUNCTION("""COMPUTED_VALUE"""),24.0) -> 24 | D32: =IFERROR(__xludf.DUMMYFUNCTION("""COMPUTED_VALUE"""),"") | E32: =IFERROR(__xludf.DUMMYFUNCTION("""COMPUTED_VALUE"""),0.0) -> 0 | H32: =IFERROR(__xludf.DUMMYFUNCTION("""COMPUTED_VALUE"""),0.0) -> 0 | K32: =IFERROR(__xludf.DUMMYFUNCTION("""COMPUTED_VALUE"""),0.0) -> 0 | L32: =IFERROR(__xludf.DUMMYFUNCTION("""COMPUTED_VALUE"""),0.0) -> 0 | M32: =IFERROR(__xludf.DUMMYFUNCTION("""COMPUTED_VALUE"""),0.0) -> 0 | N32: =IFERROR(__xludf.DUMMYFUNCTION("""COMPUTED_VALUE"""),0.0) -> 0 | O32: =IFERROR(__xludf.DUMMYFUNCTION("""COMPUTED_VALUE"""),0.0) -> 0 | P32: =IFERROR(__xludf.DUMMYFUNCTION("""COMPUTED_VALUE"""),0.0) -> 0 | Q32: =IFERROR(__xludf.DUMMYFUNCTION("""COMPUTED_VALUE"""),0.0) -> 0
B33: =IFERROR(__xludf.DUMMYFUNCTION("""COMPUTED_VALUE"""),25.0) -> 25 | D33: =IFERROR(__xludf.DUMMYFUNCTION("""COMPUTED_VALUE"""),"") | E33: =IFERROR(__xludf.DUMMYFUNCTION("""COMPUTED_VALUE"""),0.0) -> 0 | H33: =IFERROR(__xludf.DUMMYFUNCTION("""COMPUTED_VALUE"""),0.0) -> 0 | K33: =IFERROR(__xludf.DUMMYFUNCTION("""COMPUTED_VALUE"""),0.0) -> 0 | L33: =IFERROR(__xludf.DUMMYFUNCTION("""COMPUTED_VALUE"""),0.0) -> 0 | M33: =IFERROR(__xludf.DUMMYFUNCTION("""COMPUTED_VALUE"""),0.0) -> 0 | N33: =IFERROR(__xludf.DUMMYFUNCTION("""COMPUTED_VALUE"""),0.0) -> 0 | O33: =IFERROR(__xludf.DUMMYFUNCTION("""COMPUTED_VALUE"""),0.0) -> 0 | P33: =IFERROR(__xludf.DUMMYFUNCTION("""COMPUTED_VALUE"""),0.0) -> 0 | Q33: =IFERROR(__xludf.DUMMYFUNCTION("""COMPUTED_VALUE"""),0.0) -> 0
B34: =IFERROR(__xludf.DUMMYFUNCTION("""COMPUTED_VALUE"""),26.0) -> 26 | D34: =IFERROR(__xludf.DUMMYFUNCTION("""COMPUTED_VALUE"""),"") | E34: =IFERROR(__xludf.DUMMYFUNCTION("""COMPUTED_VALUE"""),0.0) -> 0 | H34: =IFERROR(__xludf.DUMMYFUNCTION("""COMPUTED_VALUE"""),0.0) -> 0 | K34: =IFERROR(__xludf.DUMMYFUNCTION("""COMPUTED_VALUE"""),0.0) -> 0 | L34: =IFERROR(__xludf.DUMMYFUNCTION("""COMPUTED_VALUE"""),0.0) -> 0 | M34: =IFERROR(__xludf.DUMMYFUNCTION("""COMPUTED_VALUE"""),0.0) -> 0 | N34: =IFERROR(__xludf.DUMMYFUNCTION("""COMPUTED_VALUE"""),0.0) -> 0 | O34: =IFERROR(__xludf.DUMMYFUNCTION("""COMPUTED_VALUE"""),0.0) -> 0 | P34: =IFERROR(__xludf.DUMMYFUNCTION("""COMPUTED_VALUE"""),0.0) -> 0 | Q34: =IFERROR(__xludf.DUMMYFUNCTION("""COMPUTED_VALUE"""),0.0) -> 0
B35: =IFERROR(__xludf.DUMMYFUNCTION("""COMPUTED_VALUE"""),27.0) -> 27 | D35: =IFERROR(__xludf.DUMMYFUNCTION("""COMPUTED_VALUE"""),"") | E35: =IFERROR(__xludf.DUMMYFUNCTION("""COMPUTED_VALUE"""),0.0) -> 0 | H35: =IFERROR(__xludf.DUMMYFUNCTION("""COMPUTED_VALUE"""),0.0) -> 0 | K35: =IFERROR(__xludf.DUMMYFUNCTION("""COMPUTED_VALUE"""),0.0) -> 0 | L35: =IFERROR(__xludf.DUMMYFUNCTION("""COMPUTED_VALUE"""),0.0) -> 0 | M35: =IFERROR(__xludf.DUMMYFUNCTION("""COMPUTED_VALUE"""),0.0) -> 0 | N35: =IFERROR(__xludf.DUMMYFUNCTION("""COMPUTED_VALUE"""),0.0) -> 0 | O35: =IFERROR(__xludf.DUMMYFUNCTION("""COMPUTED_VALUE"""),0.0) -> 0 | P35: =IFERROR(__xludf.DUMMYFUNCTION("""COMPUTED_VALUE"""),0.0) -> 0 | Q35: =IFERROR(__xludf.DUMMYFUNCTION("""COMPUTED_VALUE"""),0.0) -> 0
B36: =IFERROR(__xludf.DUMMYFUNCTION("""COMPUTED_VALUE"""),28.0) -> 28 | D36: =IFERROR(__xludf.DUMMYFUNCTION("""COMPUTED_VALUE"""),"") | E36: =IFERROR(__xludf.DUMMYFUNCTION("""COMPUTED_VALUE"""),0.0) -> 0 | H36: =IFERROR(__xludf.DUMMYFUNCTION("""COMPUTED_VALUE"""),0.0) -> 0 | K36: =IFERROR(__xludf.DUMMYFUNCTION("""COMPUTED_VALUE"""),0.0) -> 0 | L36: =IFERROR(__xludf.DUMMYFUNCTION("""COMPUTED_VALUE"""),0.0) -> 0 | M36: =IFERROR(__xludf.DUMMYFUNCTION("""COMPUTED_VALUE"""),0.0) -> 0 | N36: =IFERROR(__xludf.DUMMYFUNCTION("""COMPUTED_VALUE"""),0.0) -> 0 | O36: =IFERROR(__xludf.DUMMYFUNCTION("""COMPUTED_VALUE"""),0.0) -> 0 | P36: =IFERROR(__xludf.DUMMYFUNCTION("""COMPUTED_VALUE"""),0.0) -> 0 | Q36: =IFERROR(__xludf.DUMMYFUNCTION("""COMPUTED_VALUE"""),0.0) -> 0
B37: =IFERROR(__xludf.DUMMYFUNCTION("""COMPUTED_VALUE"""),29.0) -> 29 | D37: =IFERROR(__xludf.DUMMYFUNCTION("""COMPUTED_VALUE"""),"") | E37: =IFERROR(__xludf.DUMMYFUNCTION("""COMPUTED_VALUE"""),0.0) -> 0 | H37: =IFERROR(__xludf.DUMMYFUNCTION("""COMPUTED_VALUE"""),0.0) -> 0 | K37: =IFERROR(__xludf.DUMMYFUNCTION("""COMPUTED_VALUE"""),0.0) -> 0 | L37: =IFERROR(__xludf.DUMMYFUNCTION("""COMPUTED_VALUE"""),0.0) -> 0 | M37: =IFERROR(__xludf.DUMMYFUNCTION("""COMPUTED_VALUE"""),0.0) -> 0 | N37: =IFERROR(__xludf.DUMMYFUNCTION("""COMPUTED_VALUE"""),0.0) -> 0 | O37: =IFERROR(__xludf.DUMMYFUNCTION("""COMPUTED_VALUE"""),0.0) -> 0 | P37: =IFERROR(__xludf.DUMMYFUNCTION("""COMPUTED_VALUE"""),0.0) -> 0 | Q37: =IFERROR(__xludf.DUMMYFUNCTION("""COMPUTED_VALUE"""),0.0) -> 0
B38: =IFERROR(__xludf.DUMMYFUNCTION("""COMPUTED_VALUE"""),30.0) -> 30 | D38: =IFERROR(__xludf.DUMMYFUNCTION("""COMPUTED_VALUE"""),"") | E38: =IFERROR(__xludf.DUMMYFUNCTION("""COMPUTED_VALUE"""),0.0) -> 0 | H38: =IFERROR(__xludf.DUMMYFUNCTION("""COMPUTED_VALUE"""),0.0) -> 0 | K38: =IFERROR(__xludf.DUMMYFUNCTION("""COMPUTED_VALUE"""),0.0) -> 0 | L38: =IFERROR(__xludf.DUMMYFUNCTION("""COMPUTED_VALUE"""),0.0) -> 0 | M38: =IFERROR(__xludf.DUMMYFUNCTION("""COMPUTED_VALUE"""),0.0) -> 0 | N38: =IFERROR(__xludf.DUMMYFUNCTION("""COMPUTED_VALUE"""),0.0) -> 0 | O38: =IFERROR(__xludf.DUMMYFUNCTION("""COMPUTED_VALUE"""),0.0) -> 0 | P38: =IFERROR(__xludf.DUMMYFUNCTION("""COMPUTED_VALUE"""),0.0) -> 0 | Q38: =IFERROR(__xludf.DUMMYFUNCTION("""COMPUTED_VALUE"""),0.0) -> 0
B39: =IFERROR(__xludf.DUMMYFUNCTION("""COMPUTED_VALUE"""),31.0) -> 31 | D39: =IFERROR(__xludf.DUMMYFUNCTION("""COMPUTED_VALUE"""),"") | E39: =IFERROR(__xludf.DUMMYFUNCTION("""COMPUTED_VALUE"""),0.0) -> 0 | H39: =IFERROR(__xludf.DUMMYFUNCTION("""COMPUTED_VALUE"""),0.0) -> 0 | K39: =IFERROR(__xludf.DUMMYFUNCTION("""COMPUTED_VALUE"""),0.0) -> 0 | L39: =IFERROR(__xludf.DUMMYFUNCTION("""COMPUTED_VALUE"""),0.0) -> 0 | M39: =IFERROR(__xludf.DUMMYFUNCTION("""COMPUTED_VALUE"""),0.0) -> 0 | N39: =IFERROR(__xludf.DUMMYFUNCTION("""COMPUTED_VALUE"""),0.0) -> 0 | O39: =IFERROR(__xludf.DUMMYFUNCTION("""COMPUTED_VALUE"""),0.0) -> 0 | P39: =IFERROR(__xludf.DUMMYFUNCTION("""COMPUTED_VALUE"""),0.0) -> 0 | Q39: =IFERROR(__xludf.DUMMYFUNCTION("""COMPUTED_VALUE"""),0.0) -> 0
